File: magnetic data/MC4mox-acf-h400.ac.dat
[Header]
TITLE,MPMS AC Measurement
BYAPP,MPMS Measurement,1.1,Summary
FILEOPENTIME, 1582137952.400000 2/19/2020, 7:45:52 PM

INFO, APPNAME, MPMS MultiVu Application, Revision 1.53,  Build 056

INFO, NAME, Co(NCS)2(4-mox)2-cryst
INFO, WEIGHT, 1.300
INFO, AREA, 393.35
INFO, LENGTH, 1.000
INFO, SHAPE, 1
INFO, COMMENT, holder=58.19mg,wosk=0.43mg
INFO, SEQUENCE FILE: acf-01-1500-many-blocks.seq

STARTUPAXIS,X,4,LINEAR,AUTO,0.000000,0.000000
STARTUPAXIS,Y1,5,LINEAR,AUTO,0.000000,0.000000
STARTUPAXIS,Y2,7,LINEAR,AUTO,0.000000,0.000000


STARTUPGROUP,m' and m"
FIELDGROUP,m' and m",1,2,3,4,14,15,5,6,7,8,13,26,27,28
FIELDGROUP,Amplitude and Phase,1,2,3,4,14,15,9,10,11,12,13,26,27,28

PLOT_APPEARANCE,ALL,HORZ_GRID_ON,VERT_GRID_ON,MARKERS_AND_LINES

[Data]
Time,Comment,Field (Oe),Temperature (K),m' (emu),m' Scan Std Dev,m" (emu),m" Scan Std Dev,Amplitude (emu),Amplitude Scan Std Dev,Phase (deg),Phase Scan Std Dev,Regression Fit,Drive Amplitude (Oe),Wave Frequency (Hz),Steps per Cycle,Blocks to Average,Scans per Measurement,Clock Frequency,Amplifier Gain,AC Filter,Two Point Measurement,Scan Length,Settling Time (sec),Delta Temp (K),Rot Position (Oe),Error,% Clipped,,
1582137952.400,,4.000000e+002,3.999629e+000,2.472604e-004,0.000000e+000,1.059246e-006,0.000000e+000,2.472626e-004,0.000000e+000,2.454496e-001,0.000000e+000,9.999851e-001,3.000000e+000,1.000030e-001,7324,1,1,2,0,3,1,4.000000e+000,5,7.891655e-005,0.000000e+000,0,0.000000e+000,,
1582139025.920,,4.000000e+002,3.998885e+000,2.459681e-004,0.000000e+000,3.966473e-006,0.000000e+000,2.460001e-004,0.000000e+000,9.238696e-001,0.000000e+000,9.999952e-001,3.000000e+000,4.152052e-001,1764,1,1,2,0,3,1,4.000000e+000,5,1.561642e-004,0.000000e+000,0,0.000000e+000,,
1582139515.530,,4.000000e+002,3.998651e+000,2.408791e-004,0.000000e+000,1.024243e-005,0.000000e+000,2.410968e-004,0.000000e+000,2.434810e+000,0.000000e+000,9.999890e-001,3.000000e+000,1.723092e+000,6801,2,1,3,0,2,1,4.000000e+000,5,3.130436e-004,0.000000e+000,0,0.000000e+000,,
1582139963.500,,4.000000e+002,3.998298e+000,2.269683e-004,0.000000e+000,1.214665e-005,0.000000e+000,2.272931e-004,0.000000e+000,3.063374e+000,0.000000e+000,9.999843e-001,3.000000e+000,7.154304e+000,1638,2,1,3,0,2,1,4.000000e+000,5,7.796288e-005,0.000000e+000,0,0.000000e+000,,
1582140360.390,,4.000000e+002,3.998103e+000,2.162480e-004,0.000000e+000,7.053819e-006,0.000000e+000,2.163630e-004,0.000000e+000,1.868276e+000,0.000000e+000,9.994613e-001,3.000000e+000,2.969591e+001,6314,4,1,4,0,1,1,4.000000e+000,5,1.571178e-004,0.000000e+000,0,0.000000e+000,,
1582140744.150,,4.000000e+002,3.997947e+000,2.134886e-004,0.000000e+000,2.410265e-006,0.000000e+000,2.135023e-004,0.000000e+000,6.468360e-001,0.000000e+000,9.992712e-001,3.000000e+000,1.231932e+002,1522,10,1,4,0,0,1,4.000000e+000,5,0.000000e+000,0.000000e+000,0,0.000000e+000,,
1582141241.010,,4.000000e+002,3.998650e+000,2.123383e-004,2.682540e-008,2.440077e-007,2.281904e-008,2.123385e-004,2.680482e-008,6.584118e-002,6.165623e-003,9.930582e-001,3.000000e+000,5.122951e+002,366,40,2,4,0,0,1,4.000000e+000,5,1.016855e-003,0.000000e+000,0,0.000000e+000,,
1582142834.560,,4.000000e+002,3.899529e+000,2.631603e-004,0.000000e+000,1.395051e-006,0.000000e+000,2.631640e-004,0.000000e+000,3.037305e-001,0.000000e+000,9.999878e-001,3.000000e+000,1.000030e-001,7324,1,1,2,0,3,1,4.000000e+000,5,7.295609e-005,0.000000e+000,0,0.000000e+000,,
1582143849.640,,4.000000e+002,3.898140e+000,2.618701e-004,0.000000e+000,4.205799e-006,0.000000e+000,2.619039e-004,0.000000e+000,9.201272e-001,0.000000e+000,9.999912e-001,3.000000e+000,4.152052e-001,1764,1,1,2,0,3,1,4.000000e+000,5,7.295609e-005,0.000000e+000,0,0.000000e+000,,
1582144416.530,,4.000000e+002,3.897483e+000,2.560827e-004,0.000000e+000,1.097480e-005,0.000000e+000,2.563178e-004,0.000000e+000,2.453993e+000,0.000000e+000,9.999920e-001,3.000000e+000,1.723092e+000,6801,2,1,3,0,2,1,4.000000e+000,5,2.191067e-004,0.000000e+000,0,0.000000e+000,,
1582144880.210,,4.000000e+002,3.897958e+000,2.412377e-004,0.000000e+000,1.315380e-005,0.000000e+000,2.415961e-004,0.000000e+000,3.121036e+000,0.000000e+000,9.999862e-001,3.000000e+000,7.154304e+000,1638,2,1,3,0,2,1,4.000000e+000,5,0.000000e+000,0.000000e+000,0,0.000000e+000,,
1582145296.210,,4.000000e+002,3.897849e+000,2.298590e-004,0.000000e+000,7.792561e-006,0.000000e+000,2.299911e-004,0.000000e+000,1.941668e+000,0.000000e+000,9.995307e-001,3.000000e+000,2.969591e+001,6314,4,1,4,0,1,1,4.000000e+000,5,7.319450e-005,0.000000e+000,0,0.000000e+000,,
1582145679.370,,4.000000e+002,3.897738e+000,2.262719e-004,0.000000e+000,3.162636e-006,0.000000e+000,2.262940e-004,0.000000e+000,8.007795e-001,0.000000e+000,9.993685e-001,3.000000e+000,1.231932e+002,1522,10,1,4,0,0,1,4.000000e+000,5,0.000000e+000,0.000000e+000,0,0.000000e+000,,
1582146149.920,,4.000000e+002,3.898177e+000,2.247234e-004,6.523707e-008,6.951325e-007,1.124960e-009,2.247245e-004,6.523707e-008,1.772314e-001,2.353691e-004,9.939928e-001,3.000000e+000,5.122951e+002,366,40,2,4,0,0,1,4.000000e+000,5,2.920628e-004,0.000000e+000,0,0.000000e+000,,
1582147683.660,,4.000000e+002,3.799116e+000,2.802753e-004,0.000000e+000,1.188659e-006,0.000000e+000,2.802778e-004,0.000000e+000,2.429922e-001,0.000000e+000,9.999887e-001,3.000000e+000,1.000030e-001,7324,1,1,2,0,3,1,4.000000e+000,5,6.890297e-005,0.000000e+000,0,0.000000e+000,,
1582149687.340,,4.000000e+002,3.802969e+000,2.792215e-004,0.000000e+000,1.926185e-006,0.000000e+000,2.792281e-004,0.000000e+000,3.952436e-001,0.000000e+000,9.999913e-001,3.000000e+000,1.427445e-001,5131,1,1,2,0,3,1,4.000000e+000,5,4.100800e-004,0.000000e+000,0,0.000000e+000,,
1582150555.440,,4.000000e+002,3.800990e+000,2.779412e-004,0.000000e+000,6.016423e-006,0.000000e+000,2.780063e-004,0.000000e+000,1.240053e+000,0.000000e+000,9.999841e-001,3.000000e+000,5.925744e-001,1236,1,1,2,0,3,1,4.000000e+000,5,1.361370e-004,0.000000e+000,0,0.000000e+000,,
1582151054.770,,4.000000e+002,3.798571e+000,2.693827e-004,0.000000e+000,1.291123e-005,0.000000e+000,2.696919e-004,0.000000e+000,2.744028e+000,0.000000e+000,9.999890e-001,3.000000e+000,2.459855e+000,4764,2,1,3,0,2,1,4.000000e+000,5,2.048016e-004,0.000000e+000,0,0.000000e+000,,
1582151512.570,,4.000000e+002,3.799490e+000,2.532279e-004,0.000000e+000,1.312671e-005,0.000000e+000,2.535679e-004,0.000000e+000,2.967416e+000,0.000000e+000,9.999924e-001,3.000000e+000,1.020797e+001,1148,2,1,3,0,2,1,4.000000e+000,5,4.091263e-004,0.000000e+000,0,0.000000e+000,,
1582151945.330,,4.000000e+002,3.799661e+000,2.430438e-004,0.000000e+000,7.090664e-006,0.000000e+000,2.431472e-004,0.000000e+000,1.671098e+000,0.000000e+000,9.994777e-001,3.000000e+000,4.238246e+001,4424,4,1,4,0,1,1,4.000000e+000,5,6.890297e-005,0.000000e+000,0,0.000000e+000,,
1582152372.920,,4.000000e+002,3.799899e+000,2.400403e-004,0.000000e+000,2.915571e-006,0.000000e+000,2.400580e-004,0.000000e+000,6.958902e-001,0.000000e+000,9.992119e-001,3.000000e+000,1.758912e+002,1066,20,1,4,0,0,1,4.000000e+000,5,0.000000e+000,0.000000e+000,0,0.000000e+000,,
1582152933.770,,4.000000e+002,3.800138e+000,2.387784e-004,3.355490e-008,8.464986e-007,6.096887e-008,2.387799e-004,3.377099e-008,2.031197e-001,1.460099e-002,9.869983e-001,3.000000e+000,7.324219e+002,256,64,2,4,0,0,1,4.000000e+000,5,4.768372e-004,0.000000e+000,0,0.000000e+000,,
1582154566.600,,4.000000e+002,3.700139e+000,3.001206e-004,0.000000e+000,1.631222e-006,0.000000e+000,3.001250e-004,0.000000e+000,3.114122e-001,0.000000e+000,9.999949e-001,3.000000e+000,1.427445e-001,5131,1,1,2,0,3,1,4.000000e+000,5,6.294250e-005,0.000000e+000,0,0.000000e+000,,
1582155265.910,,4.000000e+002,3.700012e+000,2.992348e-004,0.000000e+000,5.595379e-006,0.000000e+000,2.992871e-004,0.000000e+000,1.071247e+000,0.000000e+000,9.999905e-001,3.000000e+000,5.925744e-001,1236,1,1,2,0,3,1,4.000000e+000,5,1.900196e-004,0.000000e+000,0,0.000000e+000,,
1582155817.740,,4.000000e+002,3.699949e+000,2.903802e-004,0.000000e+000,1.276378e-005,0.000000e+000,2.906606e-004,0.000000e+000,2.516839e+000,0.000000e+000,9.999894e-001,3.000000e+000,2.459855e+000,4764,2,1,3,0,2,1,4.000000e+000,5,6.294250e-005,0.000000e+000,0,0.000000e+000,,
1582156259.560,,4.000000e+002,3.699917e+000,2.746641e-004,0.000000e+000,1.327696e-005,0.000000e+000,2.749847e-004,0.000000e+000,2.767461e+000,0.000000e+000,9.999774e-001,3.000000e+000,1.020797e+001,1148,2,1,3,0,2,1,4.000000e+000,5,0.000000e+000,0.000000e+000,0,0.000000e+000,,
1582156684.580,,4.000000e+002,3.699790e+000,2.643261e-004,0.000000e+000,7.426052e-006,0.000000e+000,2.644304e-004,0.000000e+000,1.609260e+000,0.000000e+000,9.995300e-001,3.000000e+000,4.238246e+001,4424,4,1,4,0,1,1,4.000000e+000,5,0.000000e+000,0.000000e+000,0,0.000000e+000,,
1582157093.500,,4.000000e+002,3.699790e+000,2.601915e-004,0.000000e+000,3.706071e-006,0.000000e+000,2.602179e-004,0.000000e+000,8.160445e-001,0.000000e+000,9.993346e-001,3.000000e+000,1.758912e+002,1066,20,1,4,0,0,1,4.000000e+000,5,1.268387e-004,0.000000e+000,0,0.000000e+000,,
1582157651.760,,4.000000e+002,3.699933e+000,2.581406e-004,5.589397e-008,1.399678e-006,1.228841e-007,2.581444e-004,5.523544e-008,3.106634e-001,2.734127e-002,9.893398e-001,3.000000e+000,7.324219e+002,256,64,2,4,0,0,1,4.000000e+000,5,1.270771e-004,0.000000e+000,0,0.000000e+000,,
1582159398.390,,4.000000e+002,3.600077e+000,3.359132e-004,0.000000e+000,1.261018e-006,0.000000e+000,3.359155e-004,0.000000e+000,2.150873e-001,0.000000e+000,9.999823e-001,3.000000e+000,1.427445e-001,5131,1,1,2,0,3,1,4.000000e+000,5,1.180172e-004,0.000000e+000,0,0.000000e+000,,
1582160163.170,,4.000000e+002,3.599959e+000,3.347365e-004,0.000000e+000,4.456434e-006,0.000000e+000,3.347662e-004,0.000000e+000,7.627485e-001,0.000000e+000,9.999874e-001,3.000000e+000,5.925744e-001,1236,1,1,2,0,3,1,4.000000e+000,5,1.180172e-004,0.000000e+000,0,0.000000e+000,,
1582160652.780,,4.000000e+002,3.599900e+000,3.282366e-004,0.000000e+000,9.852984e-006,0.000000e+000,3.283845e-004,0.000000e+000,1.719384e+000,0.000000e+000,9.999859e-001,3.000000e+000,2.459855e+000,4764,2,1,3,0,2,1,4.000000e+000,5,1.168251e-004,0.000000e+000,0,0.000000e+000,,
1582161097.840,,4.000000e+002,3.599783e+000,3.162191e-004,0.000000e+000,1.110282e-005,0.000000e+000,3.164139e-004,0.000000e+000,2.010896e+000,0.000000e+000,9.999844e-001,3.000000e+000,1.020797e+001,1148,2,1,3,0,2,1,4.000000e+000,5,1.180172e-004,0.000000e+000,0,0.000000e+000,,
1582161504.670,,4.000000e+002,3.599871e+000,3.068830e-004,0.000000e+000,9.310094e-006,0.000000e+000,3.070241e-004,0.000000e+000,1.737684e+000,0.000000e+000,9.996133e-001,3.000000e+000,4.238246e+001,4424,4,1,4,0,1,1,4.000000e+000,5,5.793571e-005,0.000000e+000,0,0.000000e+000,,
1582161914.750,,4.000000e+002,3.599929e+000,2.994914e-004,0.000000e+000,9.793713e-006,0.000000e+000,2.996515e-004,0.000000e+000,1.872971e+000,0.000000e+000,9.994972e-001,3.000000e+000,1.758912e+002,1066,20,1,4,0,0,1,4.000000e+000,5,5.888939e-005,0.000000e+000,0,0.000000e+000,,
1582162487.350,,4.000000e+002,3.599959e+000,2.878475e-004,2.617714e-008,1.042083e-005,1.756912e-008,2.880360e-004,2.679453e-008,2.073351e+000,3.304144e-003,9.911926e-001,3.000000e+000,7.324219e+002,256,64,2,4,0,0,1,4.000000e+000,5,1.759529e-004,0.000000e+000,0,0.000000e+000,,
1582164121.430,,4.000000e+002,3.500084e+000,3.949256e-004,0.000000e+000,8.289163e-007,0.000000e+000,3.949264e-004,0.000000e+000,1.202590e-001,0.000000e+000,9.999771e-001,3.000000e+000,1.427445e-001,5131,1,1,2,0,3,1,4.000000e+000,5,1.089573e-004,0.000000e+000,0,0.000000e+000,,
1582164869.080,,4.000000e+002,3.500003e+000,3.931315e-004,0.000000e+000,2.263628e-006,0.000000e+000,3.931381e-004,0.000000e+000,3.299021e-001,0.000000e+000,9.999641e-001,3.000000e+000,5.925744e-001,1236,1,1,2,0,3,1,4.000000e+000,5,5.412102e-005,0.000000e+000,0,0.000000e+000,,
1582165344.460,,4.000000e+002,3.499976e+000,3.910003e-004,0.000000e+000,5.554465e-006,0.000000e+000,3.910397e-004,0.000000e+000,8.138766e-001,0.000000e+000,9.999822e-001,3.000000e+000,2.459855e+000,4764,2,1,3,0,2,1,4.000000e+000,5,1.089573e-004,0.000000e+000,0,0.000000e+000,,
1582165765.300,,4.000000e+002,3.499758e+000,3.841791e-004,0.000000e+000,8.870244e-006,0.000000e+000,3.842815e-004,0.000000e+000,1.322657e+000,0.000000e+000,9.998840e-001,3.000000e+000,1.020797e+001,1148,2,1,3,0,2,1,4.000000e+000,5,0.000000e+000,0.000000e+000,0,0.000000e+000,,
1582166159.450,,4.000000e+002,3.499758e+000,3.758041e-004,0.000000e+000,1.581191e-005,0.000000e+000,3.761366e-004,0.000000e+000,2.409291e+000,0.000000e+000,9.997066e-001,3.000000e+000,4.238246e+001,4424,4,1,4,0,1,1,4.000000e+000,5,1.080036e-004,0.000000e+000,0,0.000000e+000,,
1582166559.800,,4.000000e+002,3.500030e+000,3.573011e-004,0.000000e+000,2.917887e-005,0.000000e+000,3.584906e-004,0.000000e+000,4.668679e+000,0.000000e+000,9.996008e-001,3.000000e+000,1.758912e+002,1066,20,1,4,0,0,1,4.000000e+000,5,2.179146e-004,0.000000e+000,0,0.000000e+000,,
1582167145.190,,4.000000e+002,3.499907e+000,3.178431e-004,1.775806e-007,3.584869e-005,9.275445e-008,3.198584e-004,1.868620e-007,6.435045e+000,1.294515e-002,9.927933e-001,3.000000e+000,7.324219e+002,256,64,2,4,0,0,1,4.000000e+000,5,5.412102e-005,0.000000e+000,0,0.000000e+000,,
1582168785.490,,4.000000e+002,3.400028e+000,4.667834e-004,0.000000e+000,9.649897e-007,0.000000e+000,4.667844e-004,0.000000e+000,1.184484e-001,0.000000e+000,9.999765e-001,3.000000e+000,1.427445e-001,5131,1,1,2,0,3,1,4.000000e+000,5,5.102158e-005,0.000000e+000,0,0.000000e+000,,
1582169641.720,,4.000000e+002,3.399952e+000,4.672312e-004,0.000000e+000,1.477514e-006,0.000000e+000,4.672335e-004,0.000000e+000,1.811845e-001,0.000000e+000,9.999728e-001,3.000000e+000,5.925744e-001,1236,1,1,2,0,3,1,4.000000e+000,5,0.000000e+000,0.000000e+000,0,0.000000e+000,,
1582170146.930,,4.000000e+002,3.399902e+000,4.664552e-004,0.000000e+000,3.767384e-006,0.000000e+000,4.664704e-004,0.000000e+000,4.627465e-001,0.000000e+000,9.999828e-001,3.000000e+000,2.459855e+000,4764,2,1,3,0,2,1,4.000000e+000,5,9.989738e-005,0.000000e+000,0,0.000000e+000,,
1582170589.410,,4.000000e+002,3.400002e+000,4.631598e-004,0.000000e+000,1.037391e-005,0.000000e+000,4.632760e-004,0.000000e+000,1.283104e+000,0.000000e+000,9.999785e-001,3.000000e+000,1.020797e+001,1148,2,1,3,0,2,1,4.000000e+000,5,1.010895e-004,0.000000e+000,0,0.000000e+000,,
1582170985.470,,4.000000e+002,3.399877e+000,4.517300e-004,0.000000e+000,2.807544e-005,0.000000e+000,4.526016e-004,0.000000e+000,3.556412e+000,0.000000e+000,9.997893e-001,3.000000e+000,4.238246e+001,4424,4,1,4,0,1,1,4.000000e+000,5,5.006790e-005,0.000000e+000,0,0.000000e+000,,
1582171374.950,,4.000000e+002,3.399902e+000,4.148378e-004,0.000000e+000,6.097345e-005,0.000000e+000,4.192948e-004,0.000000e+000,8.361546e+000,0.000000e+000,9.997177e-001,3.000000e+000,1.758912e+002,1066,20,1,4,0,0,1,4.000000e+000,5,9.989738e-005,0.000000e+000,0,0.000000e+000,,
1582171932.000,,4.000000e+002,3.399977e+000,3.317599e-004,5.994814e-008,7.712068e-005,5.503477e-007,3.406057e-004,1.829932e-007,1.308652e+001,8.789068e-002,9.940431e-001,3.000000e+000,7.324219e+002,256,64,2,4,0,0,1,4.000000e+000,5,5.006790e-005,0.000000e+000,0,0.000000e+000,,
1582173642.060,,4.000000e+002,3.300087e+000,5.234681e-004,0.000000e+000,1.671054e-007,0.000000e+000,5.234681e-004,0.000000e+000,1.829039e-002,0.000000e+000,9.999456e-001,3.000000e+000,1.427445e-001,5131,1,1,2,0,3,1,4.000000e+000,5,4.601479e-005,0.000000e+000,0,0.000000e+000,,
1582174423.260,,4.000000e+002,3.299949e+000,5.265257e-004,0.000000e+000,1.530305e-006,0.000000e+000,5.265279e-004,0.000000e+000,1.665251e-001,0.000000e+000,9.999745e-001,3.000000e+000,5.925744e-001,1236,1,1,2,0,3,1,4.000000e+000,5,4.601479e-005,0.000000e+000,0,0.000000e+000,,
1582174877.880,,4.000000e+002,3.299903e+000,5.257227e-004,0.000000e+000,4.547227e-006,0.000000e+000,5.257424e-004,0.000000e+000,4.955662e-001,0.000000e+000,9.999809e-001,3.000000e+000,2.459855e+000,4764,2,1,3,0,2,1,4.000000e+000,5,4.601479e-005,0.000000e+000,0,0.000000e+000,,
1582175285.590,,4.000000e+002,3.299857e+000,5.224575e-004,0.000000e+000,1.511794e-005,0.000000e+000,5.226762e-004,0.000000e+000,1.657460e+000,0.000000e+000,9.999802e-001,3.000000e+000,1.020797e+001,1148,2,1,3,0,2,1,4.000000e+000,5,4.696846e-005,0.000000e+000,0,0.000000e+000,,
1582175675.950,,4.000000e+002,3.299949e+000,5.066910e-004,0.000000e+000,4.452484e-005,0.000000e+000,5.086435e-004,0.000000e+000,5.021895e+000,0.000000e+000,9.998498e-001,3.000000e+000,4.238246e+001,4424,4,1,4,0,1,1,4.000000e+000,5,4.601479e-005,0.000000e+000,0,0.000000e+000,,
1582176072.510,,4.000000e+002,3.299857e+000,4.452489e-004,0.000000e+000,9.958090e-005,0.000000e+000,4.562488e-004,0.000000e+000,1.260686e+001,0.000000e+000,9.997590e-001,3.000000e+000,1.758912e+002,1066,20,1,4,0,0,1,4.000000e+000,5,4.696846e-005,0.000000e+000,0,0.000000e+000,,
1582176630.220,,4.000000e+002,3.299949e+000,3.119401e-004,2.601251e-008,1.181692e-004,4.786693e-007,3.335724e-004,1.452504e-007,2.074769e+001,7.846867e-002,9.934560e-001,3.000000e+000,7.324219e+002,256,64,2,4,0,0,1,4.000000e+000,5,1.380444e-004,0.000000e+000,0,0.000000e+000,,
1582178533.880,,4.000000e+002,3.200098e+000,5.681616e-004,0.000000e+000,1.421576e-006,0.000000e+000,5.681634e-004,0.000000e+000,1.433573e-001,0.000000e+000,9.999787e-001,3.000000e+000,1.427445e-001,5131,1,1,2,0,3,1,4.000000e+000,5,8.511543e-005,0.000000e+000,0,0.000000e+000,,
1582179395.940,,4.000000e+002,3.200012e+000,5.681853e-004,0.000000e+000,2.739817e-006,0.000000e+000,5.681919e-004,0.000000e+000,2.762809e-001,0.000000e+000,9.999767e-001,3.000000e+000,5.925744e-001,1236,1,1,2,0,3,1,4.000000e+000,5,8.487701e-005,0.000000e+000,0,0.000000e+000,,
1582179904.000,,4.000000e+002,3.199991e+000,5.678316e-004,0.000000e+000,6.653064e-006,0.000000e+000,5.678706e-004,0.000000e+000,6.712819e-001,0.000000e+000,9.999716e-001,3.000000e+000,2.459855e+000,4764,2,1,3,0,2,1,4.000000e+000,5,2.980232e-004,0.000000e+000,0,0.000000e+000,,
1582180341.210,,4.000000e+002,3.199991e+000,5.601050e-004,0.000000e+000,2.155077e-005,0.000000e+000,5.605194e-004,0.000000e+000,2.203443e+000,0.000000e+000,9.999871e-001,3.000000e+000,1.020797e+001,1148,2,1,3,0,2,1,4.000000e+000,5,1.277924e-004,0.000000e+000,0,0.000000e+000,,
1582180744.310,,4.000000e+002,3.199863e+000,5.377813e-004,0.000000e+000,6.518309e-005,0.000000e+000,5.417172e-004,0.000000e+000,6.910962e+000,0.000000e+000,9.998847e-001,3.000000e+000,4.238246e+001,4424,4,1,4,0,1,1,4.000000e+000,5,4.291534e-005,0.000000e+000,0,0.000000e+000,,
1582181156.030,,4.000000e+002,3.199885e+000,4.432032e-004,0.000000e+000,1.408451e-004,0.000000e+000,4.650445e-004,0.000000e+000,1.762969e+001,0.000000e+000,9.997507e-001,3.000000e+000,1.758912e+002,1066,20,1,4,0,0,1,4.000000e+000,5,0.000000e+000,0.000000e+000,0,0.000000e+000,,
1582181679.080,,4.000000e+002,3.199949e+000,2.662907e-004,3.043711e-008,1.452469e-004,2.571411e-008,3.033272e-004,1.440572e-008,2.861004e+001,7.017282e-003,9.915466e-001,3.000000e+000,7.324219e+002,256,64,2,4,0,0,1,4.000000e+000,5,4.291534e-005,0.000000e+000,0,0.000000e+000,,
1582183435.330,,4.000000e+002,3.100057e+000,5.965549e-004,0.000000e+000,2.639727e-006,0.000000e+000,5.965608e-004,0.000000e+000,2.535294e-001,0.000000e+000,9.999339e-001,3.000000e+000,1.427445e-001,5131,1,1,2,0,3,1,4.000000e+000,5,3.790855e-005,0.000000e+000,0,0.000000e+000,,
1582184373.890,,4.000000e+002,3.099922e+000,5.963679e-004,0.000000e+000,3.124308e-006,0.000000e+000,5.963761e-004,0.000000e+000,3.001637e-001,0.000000e+000,9.999840e-001,3.000000e+000,5.925744e-001,1236,1,1,2,0,3,1,4.000000e+000,5,0.000000e+000,0.000000e+000,0,0.000000e+000,,
1582184897.880,,4.000000e+002,3.099883e+000,5.942576e-004,0.000000e+000,9.657190e-006,0.000000e+000,5.943360e-004,0.000000e+000,9.310232e-001,0.000000e+000,9.999875e-001,3.000000e+000,2.459855e+000,4764,2,1,3,0,2,1,4.000000e+000,5,0.000000e+000,0.000000e+000,0,0.000000e+000,,
1582185335.140,,4.000000e+002,3.099883e+000,5.876284e-004,0.000000e+000,3.114067e-005,0.000000e+000,5.884530e-004,0.000000e+000,3.033484e+000,0.000000e+000,9.999872e-001,3.000000e+000,1.020797e+001,1148,2,1,3,0,2,1,4.000000e+000,5,7.796288e-005,0.000000e+000,0,0.000000e+000,,
1582185758.780,,4.000000e+002,3.099864e+000,5.530537e-004,0.000000e+000,9.231865e-005,0.000000e+000,5.607059e-004,0.000000e+000,9.476740e+000,0.000000e+000,9.998914e-001,3.000000e+000,4.238246e+001,4424,4,1,4,0,1,1,4.000000e+000,5,3.910065e-005,0.000000e+000,0,0.000000e+000,,
1582186165.180,,4.000000e+002,3.099902e+000,4.157926e-004,0.000000e+000,1.800828e-004,0.000000e+000,4.531151e-004,0.000000e+000,2.341778e+001,0.000000e+000,9.997529e-001,3.000000e+000,1.758912e+002,1066,20,1,4,0,0,1,4.000000e+000,5,1.161098e-004,0.000000e+000,0,0.000000e+000,,
1582186742.170,,4.000000e+002,3.099999e+000,2.090470e-004,8.499340e-008,1.555752e-004,3.468575e-007,2.605846e-004,1.388912e-007,3.665705e+001,7.233883e-002,9.897903e-001,3.000000e+000,7.324219e+002,256,64,2,4,0,0,1,4.000000e+000,5,1.540184e-004,0.000000e+000,0,0.000000e+000,,
1582188490.610,,4.000000e+002,2.999717e+000,6.187736e-004,0.000000e+000,2.278271e-006,0.000000e+000,6.187778e-004,0.000000e+000,2.109572e-001,0.000000e+000,9.999820e-001,3.000000e+000,1.427445e-001,5131,1,1,2,0,3,1,4.000000e+000,5,3.519058e-004,0.000000e+000,0,0.000000e+000,,
1582189331.140,,4.000000e+002,2.999893e+000,6.157888e-004,0.000000e+000,4.967301e-006,0.000000e+000,6.158088e-004,0.000000e+000,4.621702e-001,0.000000e+000,9.999798e-001,3.000000e+000,5.925744e-001,1236,1,1,2,0,3,1,4.000000e+000,5,1.399517e-004,0.000000e+000,0,0.000000e+000,,
1582189852.930,,4.000000e+002,2.999753e+000,6.124209e-004,0.000000e+000,1.372295e-005,0.000000e+000,6.125746e-004,0.000000e+000,1.283653e+000,0.000000e+000,9.999776e-001,3.000000e+000,2.459855e+000,4764,2,1,3,0,2,1,4.000000e+000,5,8.430481e-004,0.000000e+000,0,0.000000e+000,,
1582190271.740,,4.000000e+002,2.999611e+000,6.037072e-004,0.000000e+000,4.301492e-005,0.000000e+000,6.052377e-004,0.000000e+000,4.075511e+000,0.000000e+000,9.999791e-001,3.000000e+000,1.020797e+001,1148,2,1,3,0,2,1,4.000000e+000,5,1.409054e-004,0.000000e+000,0,0.000000e+000,,
1582190689.670,,4.000000e+002,2.999331e+000,5.508240e-004,0.000000e+000,1.232938e-004,0.000000e+000,5.644541e-004,0.000000e+000,1.261684e+001,0.000000e+000,9.999000e-001,3.000000e+000,4.238246e+001,4424,4,1,4,0,1,1,4.000000e+000,5,9.841919e-004,0.000000e+000,0,0.000000e+000,,
1582191114.790,,4.000000e+002,2.999998e+000,3.669442e-004,0.000000e+000,2.090400e-004,0.000000e+000,4.223101e-004,0.000000e+000,2.966921e+001,0.000000e+000,9.997306e-001,3.000000e+000,1.758912e+002,1066,20,1,4,0,0,1,4.000000e+000,5,6.985664e-005,0.000000e+000,0,0.000000e+000,,
1582191718.530,,4.000000e+002,2.999946e+000,1.546156e-004,9.483041e-008,1.474266e-004,5.132017e-007,2.136366e-004,2.855204e-007,4.363654e+001,1.171642e-001,9.845524e-001,3.000000e+000,7.324219e+002,256,64,2,4,0,0,1,4.000000e+000,5,3.509521e-004,0.000000e+000,0,0.000000e+000,,
1582205194.880,,4.000000e+002,2.899610e+000,6.557842e-004,0.000000e+000,2.371600e-006,0.000000e+000,6.557885e-004,0.000000e+000,2.072054e-001,0.000000e+000,9.999842e-001,3.000000e+000,1.427445e-001,5131,1,1,2,0,3,1,4.000000e+000,5,6.389618e-005,0.000000e+000,0,0.000000e+000,,
1582206128.950,,4.000000e+002,2.899865e+000,6.521801e-004,0.000000e+000,7.423467e-006,0.000000e+000,6.522223e-004,0.000000e+000,6.521434e-001,0.000000e+000,9.999883e-001,3.000000e+000,5.925744e-001,1236,1,1,2,0,3,1,4.000000e+000,5,4.451275e-004,0.000000e+000,0,0.000000e+000,,
1582206632.830,,4.000000e+002,2.899547e+000,6.486846e-004,0.000000e+000,2.048623e-005,0.000000e+000,6.490080e-004,0.000000e+000,1.808868e+000,0.000000e+000,9.999909e-001,3.000000e+000,2.459855e+000,4764,2,1,3,0,2,1,4.000000e+000,5,1.909733e-004,0.000000e+000,0,0.000000e+000,,
1582207086.850,,4.000000e+002,2.899864e+000,6.326145e-004,0.000000e+000,6.265319e-005,0.000000e+000,6.357094e-004,0.000000e+000,5.656044e+000,0.000000e+000,9.999927e-001,3.000000e+000,1.020797e+001,1148,2,1,3,0,2,1,4.000000e+000,5,3.180504e-004,0.000000e+000,0,0.000000e+000,,
1582207499.500,,4.000000e+002,2.899610e+000,5.498295e-004,0.000000e+000,1.661267e-004,0.000000e+000,5.743784e-004,0.000000e+000,1.681178e+001,0.000000e+000,9.999064e-001,3.000000e+000,4.238246e+001,4424,4,1,4,0,1,1,4.000000e+000,5,6.389618e-005,0.000000e+000,0,0.000000e+000,,
1582207918.800,,4.000000e+002,2.899769e+000,3.093081e-004,0.000000e+000,2.339871e-004,0.000000e+000,3.878420e-004,0.000000e+000,3.710698e+001,0.000000e+000,9.996969e-001,3.000000e+000,1.758912e+002,1066,20,1,4,0,0,1,4.000000e+000,5,1.280308e-004,0.000000e+000,0,0.000000e+000,,
1582208479.040,,4.000000e+002,2.899785e+000,1.086991e-004,1.712319e-007,1.320551e-004,2.695299e-007,1.710381e-004,9.927575e-008,5.054102e+001,1.016677e-001,9.765546e-001,3.000000e+000,7.324219e+002,256,64,2,4,0,0,1,4.000000e+000,5,5.090237e-004,0.000000e+000,0,0.000000e+000,,
1582210398.360,,4.000000e+002,2.799553e+000,6.638551e-004,0.000000e+000,4.311626e-006,0.000000e+000,6.638690e-004,0.000000e+000,3.721212e-001,0.000000e+000,9.999903e-001,3.000000e+000,1.427445e-001,5131,1,1,2,0,3,1,4.000000e+000,5,1.426935e-003,0.000000e+000,0,0.000000e+000,,
1582211333.250,,4.000000e+002,2.799667e+000,6.594973e-004,0.000000e+000,1.044321e-005,0.000000e+000,6.595800e-004,0.000000e+000,9.072093e-001,0.000000e+000,9.999868e-001,3.000000e+000,5.925744e-001,1236,1,1,2,0,3,1,4.000000e+000,5,7.431507e-004,0.000000e+000,0,0.000000e+000,,
1582211871.460,,4.000000e+002,2.800011e+000,6.545473e-004,0.000000e+000,2.810969e-005,0.000000e+000,6.551506e-004,0.000000e+000,2.459070e+000,0.000000e+000,9.999920e-001,3.000000e+000,2.459855e+000,4764,2,1,3,0,2,1,4.000000e+000,5,5.698204e-005,0.000000e+000,0,0.000000e+000,,
1582212299.220,,4.000000e+002,2.800496e+000,6.300716e-004,0.000000e+000,8.425414e-005,0.000000e+000,6.356799e-004,0.000000e+000,7.616497e+000,0.000000e+000,9.999914e-001,3.000000e+000,1.020797e+001,1148,2,1,3,0,2,1,4.000000e+000,5,7.998943e-004,0.000000e+000,0,0.000000e+000,,
1582212713.030,,4.000000e+002,2.799953e+000,5.101599e-004,0.000000e+000,2.025281e-004,0.000000e+000,5.488904e-004,0.000000e+000,2.165256e+001,0.000000e+000,9.998817e-001,3.000000e+000,4.238246e+001,4424,4,1,4,0,1,1,4.000000e+000,5,5.698204e-005,0.000000e+000,0,0.000000e+000,,
1582213091.080,,4.000000e+002,2.799953e+000,2.390244e-004,0.000000e+000,2.290061e-004,0.000000e+000,3.310234e-004,0.000000e+000,4.377376e+001,0.000000e+000,9.996030e-001,3.000000e+000,1.758912e+002,1066,20,1,4,0,0,1,4.000000e+000,5,5.698204e-005,0.000000e+000,0,0.000000e+000,,
1582213629.080,,4.000000e+002,2.800239e+000,7.458015e-005,1.151064e-007,1.087974e-004,8.714396e-008,1.319055e-004,1.369567e-007,5.556952e+001,1.983937e-002,9.628253e-001,3.000000e+000,7.324219e+002,256,64,2,4,0,0,1,4.000000e+000,5,5.710125e-004,0.000000e+000,0,0.000000e+000,,
1582215475.290,,4.000000e+002,2.700189e+000,6.714698e-004,0.000000e+000,2.772956e-006,0.000000e+000,6.714755e-004,0.000000e+000,2.366120e-001,0.000000e+000,9.999133e-001,3.000000e+000,1.427445e-001,5131,1,1,2,0,3,1,4.000000e+000,5,2.548695e-004,0.000000e+000,0,0.000000e+000,,
1582216265.060,,4.000000e+002,2.700138e+000,6.637619e-004,0.000000e+000,1.412957e-005,0.000000e+000,6.639122e-004,0.000000e+000,1.219477e+000,0.000000e+000,9.999921e-001,3.000000e+000,5.925744e-001,1236,1,1,2,0,3,1,4.000000e+000,5,1.528263e-004,0.000000e+000,0,0.000000e+000,,
1582216792.350,,4.000000e+002,2.699908e+000,6.564184e-004,0.000000e+000,3.908965e-005,0.000000e+000,6.575813e-004,0.000000e+000,3.407933e+000,0.000000e+000,9.999883e-001,3.000000e+000,2.459855e+000,4764,2,1,3,0,2,1,4.000000e+000,5,1.020432e-004,0.000000e+000,0,0.000000e+000,,
1582217205.720,,4.000000e+002,2.700214e+000,6.185365e-004,0.000000e+000,1.113433e-004,0.000000e+000,6.284782e-004,0.000000e+000,1.020457e+001,0.000000e+000,9.999931e-001,3.000000e+000,1.020797e+001,1148,2,1,3,0,2,1,4.000000e+000,5,5.109310e-004,0.000000e+000,0,0.000000e+000,,
1582217613.210,,4.000000e+002,2.700036e+000,4.523936e-004,0.000000e+000,2.331047e-004,0.000000e+000,5.089183e-004,0.000000e+000,2.726068e+001,0.000000e+000,9.998585e-001,3.000000e+000,4.238246e+001,4424,4,1,4,0,1,1,4.000000e+000,5,5.102158e-005,0.000000e+000,0,0.000000e+000,,
1582218044.040,,4.000000e+002,2.699985e+000,1.752529e-004,0.000000e+000,2.093134e-004,0.000000e+000,2.729939e-004,0.000000e+000,5.006139e+001,0.000000e+000,9.995086e-001,3.000000e+000,1.758912e+002,1066,20,1,4,0,0,1,4.000000e+000,5,2.551079e-004,0.000000e+000,0,0.000000e+000,,
1582218570.560,,4.000000e+002,2.699895e+000,4.998826e-005,5.500905e-008,8.620281e-005,9.374484e-008,9.964814e-005,5.350675e-008,5.989093e+001,5.440113e-002,9.371672e-001,3.000000e+000,7.324219e+002,256,64,2,4,0,0,1,4.000000e+000,5,4.591942e-004,0.000000e+000,0,0.000000e+000,,
1582220562.320,,4.000000e+002,2.600197e+000,6.684990e-004,0.000000e+000,8.491153e-006,0.000000e+000,6.685529e-004,0.000000e+000,7.277215e-001,0.000000e+000,9.999889e-001,3.000000e+000,1.427445e-001,5131,1,1,2,0,3,1,4.000000e+000,5,2.269745e-004,0.000000e+000,0,0.000000e+000,,
1582221417.510,,4.000000e+002,2.599764e+000,6.654022e-004,0.000000e+000,1.989762e-005,0.000000e+000,6.656997e-004,0.000000e+000,1.712814e+000,0.000000e+000,9.999850e-001,3.000000e+000,5.925744e-001,1236,1,1,2,0,3,1,4.000000e+000,5,0.000000e+000,0.000000e+000,0,0.000000e+000,,
1582221915.630,,4.000000e+002,2.599787e+000,6.526192e-004,0.000000e+000,5.377868e-005,0.000000e+000,6.548313e-004,0.000000e+000,4.710779e+000,0.000000e+000,9.999905e-001,3.000000e+000,2.459855e+000,4764,2,1,3,0,2,1,4.000000e+000,5,2.269745e-004,0.000000e+000,0,0.000000e+000,,
1582222311.260,,4.000000e+002,2.599673e+000,5.940556e-004,0.000000e+000,1.431726e-004,0.000000e+000,6.110651e-004,0.000000e+000,1.355037e+001,0.000000e+000,9.999924e-001,3.000000e+000,1.020797e+001,1148,2,1,3,0,2,1,4.000000e+000,5,2.729893e-004,0.000000e+000,0,0.000000e+000,,
1582222716.280,,4.000000e+002,2.600151e+000,3.807744e-004,0.000000e+000,2.513780e-004,0.000000e+000,4.562676e-004,0.000000e+000,3.343182e+001,0.000000e+000,9.998402e-001,3.000000e+000,4.238246e+001,4424,4,1,4,0,1,1,4.000000e+000,5,7.739067e-004,0.000000e+000,0,0.000000e+000,,
1582223146.900,,4.000000e+002,2.599878e+000,1.233442e-004,0.000000e+000,1.790623e-004,0.000000e+000,2.174330e-004,0.000000e+000,5.543960e+001,0.000000e+000,9.991605e-001,3.000000e+000,1.758912e+002,1066,20,1,4,0,0,1,4.000000e+000,5,4.601479e-005,0.000000e+000,0,0.000000e+000,,
1582223701.260,,4.000000e+002,2.600037e+000,3.395110e-005,5.173176e-008,6.701172e-005,3.727002e-007,7.512155e-005,3.090838e-007,6.313121e+001,1.636707e-001,8.911722e-001,3.000000e+000,7.324219e+002,256,64,2,4,0,0,1,4.000000e+000,5,4.551411e-004,0.000000e+000,0,0.000000e+000,,
1582225772.010,,4.000000e+002,2.499969e+000,6.690701e-004,0.000000e+000,1.167759e-005,0.000000e+000,6.691720e-004,0.000000e+000,9.999083e-001,0.000000e+000,9.999768e-001,3.000000e+000,1.427445e-001,5131,1,1,2,0,3,1,4.000000e+000,5,8.039474e-004,0.000000e+000,0,0.000000e+000,,
1582226663.500,,4.000000e+002,2.500029e+000,6.634337e-004,0.000000e+000,2.822212e-005,0.000000e+000,6.640337e-004,0.000000e+000,2.435864e+000,0.000000e+000,9.999886e-001,3.000000e+000,5.925744e-001,1236,1,1,2,0,3,1,4.000000e+000,5,4.005432e-005,0.000000e+000,0,0.000000e+000,,
1582227230.220,,4.000000e+002,2.499989e+000,6.424660e-004,0.000000e+000,7.238505e-005,0.000000e+000,6.465309e-004,0.000000e+000,6.428264e+000,0.000000e+000,9.999898e-001,3.000000e+000,2.459855e+000,4764,2,1,3,0,2,1,4.000000e+000,5,3.619194e-004,0.000000e+000,0,0.000000e+000,,
1582227676.440,,4.000000e+002,2.499707e+000,5.551462e-004,0.000000e+000,1.765465e-004,0.000000e+000,5.825427e-004,0.000000e+000,1.764160e+001,0.000000e+000,9.999890e-001,3.000000e+000,1.020797e+001,1148,2,1,3,0,2,1,4.000000e+000,5,2.808571e-004,0.000000e+000,0,0.000000e+000,,
1582228134.130,,4.000000e+002,2.499929e+000,3.040586e-004,0.000000e+000,2.511734e-004,0.000000e+000,3.943853e-004,0.000000e+000,3.955906e+001,0.000000e+000,9.997952e-001,3.000000e+000,4.238246e+001,4424,4,1,4,0,1,1,4.000000e+000,5,4.019737e-004,0.000000e+000,0,0.000000e+000,,
1582228569.640,,4.000000e+002,2.499707e+000,8.642416e-005,0.000000e+000,1.469070e-004,0.000000e+000,1.704429e-004,0.000000e+000,5.953205e+001,0.000000e+000,9.986393e-001,3.000000e+000,1.758912e+002,1066,20,1,4,0,0,1,4.000000e+000,5,3.609657e-004,0.000000e+000,0,0.000000e+000,,
1582229144.490,,4.000000e+002,2.499969e+000,2.395459e-005,9.076853e-009,5.188670e-005,1.468606e-008,5.714939e-005,1.713759e-008,6.521860e+001,2.087793e-003,8.307967e-001,3.000000e+000,7.324219e+002,256,64,2,4,0,0,1,4.000000e+000,5,1.611710e-004,0.000000e+000,0,0.000000e+000,,
1582231918.280,,4.000000e+002,2.399809e+000,6.693069e-004,0.000000e+000,1.762668e-005,0.000000e+000,6.695390e-004,0.000000e+000,1.508577e+000,0.000000e+000,9.999864e-001,3.000000e+000,1.427445e-001,5131,1,1,2,0,3,1,4.000000e+000,5,3.504753e-005,0.000000e+000,0,0.000000e+000,,
1582232754.740,,4.000000e+002,2.399880e+000,6.600393e-004,0.000000e+000,3.957819e-005,0.000000e+000,6.612248e-004,0.000000e+000,3.431540e+000,0.000000e+000,9.999720e-001,3.000000e+000,5.925744e-001,1236,1,1,2,0,3,1,4.000000e+000,5,3.504753e-005,0.000000e+000,0,0.000000e+000,,
1582233279.330,,4.000000e+002,2.399985e+000,6.249132e-004,0.000000e+000,9.596910e-005,0.000000e+000,6.322393e-004,0.000000e+000,8.730810e+000,0.000000e+000,9.999917e-001,3.000000e+000,2.459855e+000,4764,2,1,3,0,2,1,4.000000e+000,5,3.859997e-004,0.000000e+000,0,0.000000e+000,,
1582233741.310,,4.000000e+002,2.400003e+000,5.007116e-004,0.000000e+000,2.058888e-004,0.000000e+000,5.413892e-004,0.000000e+000,2.235209e+001,0.000000e+000,9.999865e-001,3.000000e+000,1.020797e+001,1148,2,1,3,0,2,1,4.000000e+000,5,7.009506e-005,0.000000e+000,0,0.000000e+000,,
1582234165.720,,4.000000e+002,2.400073e+000,2.333555e-004,0.000000e+000,2.334191e-004,0.000000e+000,3.300595e-004,0.000000e+000,4.500780e+001,0.000000e+000,9.997360e-001,3.000000e+000,4.238246e+001,4424,4,1,4,0,1,1,4.000000e+000,5,7.009506e-005,0.000000e+000,0,0.000000e+000,,
1582234647.030,,4.000000e+002,2.400178e+000,6.138808e-005,0.000000e+000,1.169045e-004,0.000000e+000,1.320423e-004,0.000000e+000,6.229545e+001,0.000000e+000,9.976449e-001,3.000000e+000,1.758912e+002,1066,20,1,4,0,0,1,4.000000e+000,5,7.019043e-004,0.000000e+000,0,0.000000e+000,,
1582235245.880,,4.000000e+002,2.400047e+000,1.764679e-005,8.855751e-008,3.938749e-005,1.501739e-007,4.315998e-005,1.008398e-007,6.586617e+001,1.887966e-001,7.520419e-001,3.000000e+000,7.324219e+002,256,64,2,4,0,0,1,4.000000e+000,5,2.098083e-004,0.000000e+000,0,0.000000e+000,,
1582238532.240,,4.000000e+002,2.209172e+000,6.596864e-004,0.000000e+000,3.984891e-005,0.000000e+000,6.608889e-004,0.000000e+000,3.456799e+000,0.000000e+000,9.999925e-001,3.000000e+000,1.427445e-001,5131,1,1,2,0,3,1,4.000000e+000,5,4.775047e-003,0.000000e+000,0,0.000000e+000,,
1582239510.900,,4.000000e+002,2.210124e+000,6.268677e-004,0.000000e+000,7.933166e-005,0.000000e+000,6.318676e-004,0.000000e+000,7.212581e+000,0.000000e+000,9.999864e-001,3.000000e+000,5.925744e-001,1236,1,1,2,0,3,1,4.000000e+000,5,5.292892e-005,0.000000e+000,0,0.000000e+000,,
1582240062.580,,4.000000e+002,2.208731e+000,5.451789e-004,0.000000e+000,1.578754e-004,0.000000e+000,5.675780e-004,0.000000e+000,1.615020e+001,0.000000e+000,9.999840e-001,3.000000e+000,2.459855e+000,4764,2,1,3,0,2,1,4.000000e+000,5,1.139879e-003,0.000000e+000,0,0.000000e+000,,
1582240593.320,,4.000000e+002,2.194623e+000,3.383413e-004,0.000000e+000,2.312252e-004,0.000000e+000,4.098048e-004,0.000000e+000,3.434902e+001,0.000000e+000,9.999776e-001,3.000000e+000,1.020797e+001,1148,2,1,3,0,2,1,4.000000e+000,5,3.890991e-004,0.000000e+000,0,0.000000e+000,,
1582241029.980,,4.000000e+002,2.197588e+000,1.172049e-004,0.000000e+000,1.626423e-004,0.000000e+000,2.004732e-004,0.000000e+000,5.422234e+001,0.000000e+000,9.993885e-001,3.000000e+000,4.238246e+001,4424,4,1,4,0,1,1,4.000000e+000,5,1.224041e-003,0.000000e+000,0,0.000000e+000,,
1582241431.710,,4.000000e+002,2.193031e+000,3.184313e-005,0.000000e+000,6.496414e-005,0.000000e+000,7.234863e-005,0.000000e+000,6.388754e+001,0.000000e+000,9.918807e-001,3.000000e+000,1.758912e+002,1066,20,1,4,0,0,1,4.000000e+000,5,3.619194e-004,0.000000e+000,0,0.000000e+000,,
1582241977.990,,4.000000e+002,2.197862e+000,1.188192e-005,3.978728e-008,2.142283e-005,2.937353e-007,2.449731e-005,2.375691e-007,6.098558e+001,4.146215e-001,4.837970e-001,3.000000e+000,7.324219e+002,256,64,2,4,0,0,1,4.000000e+000,5,1.812196e-002,0.000000e+000,0,0.000000e+000,,
1582244289.810,,4.000000e+002,1.999864e+000,6.330030e-004,0.000000e+000,6.529063e-005,0.000000e+000,6.363612e-004,0.000000e+000,5.888906e+000,0.000000e+000,9.999860e-001,3.000000e+000,1.427445e-001,5131,1,1,2,0,3,1,4.000000e+000,5,2.350807e-004,0.000000e+000,0,0.000000e+000,,
1582245106.990,,4.000000e+002,1.999817e+000,5.767590e-004,0.000000e+000,1.196320e-004,0.000000e+000,5.890355e-004,0.000000e+000,1.171819e+001,0.000000e+000,9.999867e-001,3.000000e+000,5.925744e-001,1236,1,1,2,0,3,1,4.000000e+000,5,4.696846e-005,0.000000e+000,0,0.000000e+000,,
1582245645.810,,4.000000e+002,2.000028e+000,4.398896e-004,0.000000e+000,1.988822e-004,0.000000e+000,4.827597e-004,0.000000e+000,2.432860e+001,0.000000e+000,9.999776e-001,3.000000e+000,2.459855e+000,4764,2,1,3,0,2,1,4.000000e+000,5,9.405613e-005,0.000000e+000,0,0.000000e+000,,
1582246125.690,,4.000000e+002,2.000075e+000,2.111577e-004,0.000000e+000,2.001998e-004,0.000000e+000,2.909769e-004,0.000000e+000,4.347409e+001,0.000000e+000,9.999664e-001,3.000000e+000,1.020797e+001,1148,2,1,3,0,2,1,4.000000e+000,5,9.417534e-005,0.000000e+000,0,0.000000e+000,,
1582246550.820,,4.000000e+002,1.999934e+000,6.538242e-005,0.000000e+000,1.036898e-004,0.000000e+000,1.225824e-004,0.000000e+000,5.776620e+001,0.000000e+000,9.984812e-001,3.000000e+000,4.238246e+001,4424,4,1,4,0,1,1,4.000000e+000,5,9.405613e-005,0.000000e+000,0,0.000000e+000,,
1582246992.690,,4.000000e+002,1.999958e+000,2.247984e-005,0.000000e+000,3.724059e-005,0.000000e+000,4.349948e-005,0.000000e+000,5.888322e+001,0.000000e+000,9.742488e-001,3.000000e+000,1.758912e+002,1066,20,1,4,0,0,1,4.000000e+000,5,2.350807e-004,0.000000e+000,0,0.000000e+000,,
1582247557.160,,4.000000e+002,1.999899e+000,1.096399e-005,4.164780e-009,1.326694e-005,2.253071e-008,1.721106e-005,2.002001e-008,5.042919e+001,3.709463e-002,3.500968e-001,3.000000e+000,7.324219e+002,256,64,2,4,1,0,1,4.000000e+000,5,2.348423e-004,0.000000e+000,0,0.000000e+000,,
1582249777.910,,4.000000e+002,1.808093e+000,5.778080e-004,0.000000e+000,1.109935e-004,0.000000e+000,5.883720e-004,0.000000e+000,1.087372e+001,0.000000e+000,9.999859e-001,3.000000e+000,1.427445e-001,5131,1,1,2,0,3,1,4.000000e+000,5,6.592274e-005,0.000000e+000,0,0.000000e+000,,
1582250631.400,,4.000000e+002,1.800687e+000,4.590043e-004,0.000000e+000,1.796402e-004,0.000000e+000,4.929052e-004,0.000000e+000,2.137385e+001,0.000000e+000,9.999378e-001,3.000000e+000,5.925744e-001,1236,1,1,2,0,3,1,4.000000e+000,5,0.000000e+000,0.000000e+000,0,0.000000e+000,,
1582251184.330,,4.000000e+002,1.798804e+000,2.460926e-004,0.000000e+000,1.973967e-004,0.000000e+000,3.154791e-004,0.000000e+000,3.873392e+001,0.000000e+000,9.999777e-001,3.000000e+000,2.459855e+000,4764,2,1,3,0,2,1,4.000000e+000,5,3.302097e-005,0.000000e+000,0,0.000000e+000,,
1582251666.690,,4.000000e+002,1.797661e+000,8.553042e-005,0.000000e+000,1.127698e-004,0.000000e+000,1.415361e-004,0.000000e+000,5.282145e+001,0.000000e+000,9.999580e-001,3.000000e+000,1.020797e+001,1148,2,1,3,0,2,1,4.000000e+000,5,1.629591e-004,0.000000e+000,0,0.000000e+000,,
1582252120.540,,4.000000e+002,1.797042e+000,3.193165e-005,0.000000e+000,4.191746e-005,0.000000e+000,5.269444e-005,0.000000e+000,5.270078e+001,0.000000e+000,9.928193e-001,3.000000e+000,4.238246e+001,4424,4,1,4,0,1,1,4.000000e+000,5,9.703636e-005,0.000000e+000,0,0.000000e+000,,
1582252533.580,,4.000000e+002,1.797596e+000,1.724351e-005,0.000000e+000,1.453961e-005,0.000000e+000,2.255524e-005,0.000000e+000,4.013737e+001,0.000000e+000,9.043739e-001,3.000000e+000,1.758912e+002,1066,20,1,4,1,0,1,4.000000e+000,5,1.630783e-004,0.000000e+000,0,0.000000e+000,,
1582253057.510,,4.000000e+002,1.799139e+000,9.787709e-006,1.035427e-010,6.710666e-006,6.048705e-008,1.186728e-005,3.428941e-008,3.443538e+001,2.405761e-001,1.816915e-001,3.000000e+000,7.324219e+002,256,64,2,4,1,0,1,4.000000e+000,5,9.799004e-005,0.000000e+000,0,0.000000e+000,,
1582253497.020,,4.000000e+002,1.800408e+000,6.735536e-006,4.974249e-007,6.747939e-006,2.144904e-006,9.534260e-006,1.162801e-006,4.505270e+001,1.127313e+001,3.956180e-002,3.000000e+000,1.488095e+003,126,64,2,4,1,0,1,4.000000e+000,5,3.609657e-004,0.000000e+000,0,0.000000e+000,,