File: heat capacity project/HC_AJ1396_Co-morph.dat
[Header]
TITLE,HC_AJ1396_Co-morph.dat
BYAPP,HeatCapacity,3.8.2,1.7
INFO,4.91,MASS:Sample Mass (mg)
INFO,,MASSERR:Sample Mass Error (mg)
INFO,349.33,MOLWGHT:Formula Weight (g/mole)
INFO,,ATOMS:Atoms per Formula Unit
INFO,PPMS Heat Capacity Option 3.8.2 Build 2,APPNAME
DATATYPE,TIME,1
DATATYPE,COMMENT,2
STARTUPAXIS, X, 8, LINEAR, AUTO
STARTUPAXIS, Y1, 10, LINEAR, AUTO
[Data]
Time Stamp (Seconds),Comment (),System Status (Code),Puck Temp (Kelvin),System Temp (Kelvin),Field (Oersted),Pressure (Torr),Sample Temp (Kelvin),Temp Rise (Kelvin),Samp HC (µJ/K),Samp HC Err (µJ/K),Addenda HC (µJ/K),Addenda HC Err (µJ/K),Total HC (µJ/K),Total HC Err (µJ/K),Fit Deviation (ChiSquare),Time Const tau1 (seconds),Time Const tau2 (seconds),Sample Coupling (Percent),Debye Temp (Kelvin),Debye Temp Err (Kelvin),Cal Correction (Factor),Therm Resist (Ohms),Htr Resist (Ohms),Puck Resist (Ohms),Wire Cond (W/K),Meas Time (seconds),Temp Squared (K^2),Samp HC/Temp (µJ/K/K),Addenda Offset HC (µJ/K)
6170683.63,CALFILE: Puck1073_1.cal - Addenda #30 measured on 3/13/2018 from 2.0245343 to 60.507468 K
6170683.78,,5905,60.0045,60.1441,0,9.3E-6,60.553205,1.2454805,1501.4437,2.288,795.95218,0.7828,2297.3959,2.288,0.049056558,37.995948,0.062576146,99.2734,0,0,1,,,,6.0654E-5,78.80646,3666.6907,24.795445,0
6170984.97,,5905,59.9954,60.1541,0,9.3E-6,60.525788,1.2128005,1501.3205,1.643,795.33614,0.783,2296.6567,1.643,0.2119315,38.296449,0.075009464,99.135844,0,0,1,,,,6.0194E-5,75.9919,3663.371,24.804642,0
6171627.41,,5905,53.3435,53.5143,0,9.3E-6,53.82789,1.1403671,1325.5872,1.919,638.68682,0.7824,1964.274,1.919,4.7262322,36.268728,0.08742427,98.902501,0,0,1,,,,5.4433E-5,76.5929,2897.4417,24.626401,0
6171917.17,,5905,53.3644,53.4812,0,9.3E-6,53.847208,1.112058,1316.7112,1.452,639.07338,0.7826,1955.7846,1.452,0.38946201,35.203718,0.059790457,99.22849,0,0,1,,,,5.5752E-5,72.53746,2899.5218,24.452729,0
6172533.55,,5905,47.4391,47.6037,0,9.2E-6,47.868534,1.0213763,1154.6,1.753,520.90677,0.6815,1675.5067,1.753,5.4993893,33.393197,0.077580745,98.916117,0,0,1,,,,5.0437E-5,70.40744,2291.3966,24.120228,0
6172805.13,,5905,47.4582,47.5789,0,9.3E-6,47.893196,0.99711163,1145.9279,1.294,521.33653,0.6819,1667.2644,1.294,0.46862965,32.324095,0.050670625,99.270881,0,0,1,,,,5.1759E-5,66.78639,2293.7582,23.926738,0
6173414.64,,5905,42.1841,42.3464,0,9.3E-6,42.586435,0.91564932,994.65133,1.793,423.51302,0.5799,1418.1643,1.793,0.28233997,30.606959,0.066927002,98.956134,0,0,1,,,,4.6576E-5,64.64819,1813.6045,23.35606,0
6173664.73,,5905,42.2088,42.3307,0,9.3E-6,42.603277,0.89305505,990.20187,1.089,423.81249,0.5803,1414.0144,1.089,0.80600675,29.74536,0.046316342,99.258222,0,0,1,,,,4.7712E-5,61.21392,1815.0392,23.242387,0
6174372.91,,5905,37.5435,37.6718,0,9.3E-6,37.916884,0.81696555,848.08534,1.206,345.42176,0.4713,1193.5071,1.206,0.14890473,27.214398,0.039554515,99.293197,0,0,1,,,,4.4014E-5,59.49072,1437.6901,22.366958,0
6174599.66,,5905,37.5348,37.6634,0,9.3E-6,37.889997,0.78696403,850.1207,1.008,345.06262,0.4708,1195.1833,1.008,0.23982689,27.186414,0.039061252,99.30027,0,0,1,,,,4.4119E-5,54.4288,1435.6518,22.436547,0
6175120.14,,5905,33.3496,33.5459,0,9.3E-6,33.686586,0.73527755,728.48242,1.524,280.94266,0.3784,1009.4251,1.524,0.43528828,25.864811,0.058681082,98.869862,0,0,1,,,,3.926E-5,54.37283,1134.7861,21.625297,0
6175306.64,,5905,33.3853,33.5243,0,9.2E-6,33.722481,0.71817498,723.74542,0.7808,281.45058,0.3791,1005.196,0.7808,1.6453922,24.888753,0.03466391,99.308952,0,0,1,,,,4.0533E-5,51.72962,1137.2057,21.461808,0
6175805.81,,5905,29.6507,29.8451,0,9.3E-6,29.960521,0.65760296,612.20032,1.047,227.7287,0.3623,839.92902,1.047,5.1169743,23.353309,0.045817924,99.006537,0,0,1,,,,3.6158E-5,49.77751,897.63281,20.433567,0
6175980.09,,5905,29.6847,29.8546,0,9.3E-6,29.994928,0.6411639,612.63402,0.9126,228.21376,0.3621,840.84778,0.9126,1.4869399,23.203731,0.042152055,99.080785,0,0,1,,,,3.6416E-5,46.70662,899.69573,20.424587,0
6176448.34,,5905,26.3583,26.5627,0,9.3E-6,26.646641,0.59531648,513.86576,1.056,182.88604,0.2908,696.7518,1.056,1.1762586,21.533522,0.045098741,98.917035,0,0,1,,,,3.255E-5,46.40746,710.04346,19.284448,0
6176609.52,,5905,26.3944,26.5817,0,9.3E-6,26.68862,0.57672346,509.43146,0.759,183.43523,0.2924,692.86669,0.759,0.47500077,20.904446,0.031919987,99.215044,0,0,1,,,,3.3286E-5,43.06704,712.28244,19.087966,0
6177093.67,,5905,23.4564,23.5874,0,9.3E-6,23.72048,0.50724813,418.92265,1.358,146.33589,0.208,565.25854,1.342,0.11096908,17.714297,0,100,0,0,1,,,,3.191E-5,41.80889,562.66116,17.6608,0
6177232.91,,5905,23.4581,23.6468,0,9.3E-6,23.709574,0.48684442,422.13796,0.66,146.25797,0.2079,568.39594,0.66,2.3247122,19.110812,0.031916356,99.125276,0,0,1,,,,2.9887E-5,35.42859,562.14392,17.804536,0
6177650.7,,5905,20.8808,20.9841,0,9.3E-6,21.106391,0.4708502,350.16458,0.756,116.72813,0.1666,466.8927,0.756,1.3123923,17.454185,0.032177689,99.01554,0,0,1,,,,2.6899E-5,38.22162,445.47976,16.590452,0
6177825.58,,5905,20.8489,21.0392,0,9.3E-6,21.093855,0.45933725,347.5031,0.9715,116.62835,0.1664,464.13145,0.9715,0.17101772,17.614341,0.034430167,98.959687,0,0,1,,,,2.6505E-5,34.90837,444.95073,16.474139,0
6178200.27,,5905,18.5627,18.701,0,9.3E-6,18.785625,0.42180585,282.74276,0.4346,92.093077,0.1247,374.83583,0.4346,0.52216368,15.40042,0.018070308,99.366297,0,0,1,,,,2.4428E-5,35.22868,352.89972,15.051016,0
6178343.98,,5905,18.5686,18.6954,0,9.2E-6,18.778547,0.39749742,281.89641,0.3802,92.059178,0.1246,373.95558,0.3802,5.867741,15.253689,0.018073818,99.360933,0,0,1,,,,2.4605E-5,30.80084,352.63382,15.01162,0
6178704.63,,5905,16.5073,16.6415,0,9.2E-6,16.708956,0.36295604,231.05403,0.3616,72.192553,0.09726,303.24658,0.3616,0.59496141,14.034648,0.017082126,99.328251,0,0,1,,,,2.1692E-5,30.50738,279.18921,13.828155,0
6178822.14,,5905,16.5165,16.6363,0,9.3E-6,16.708259,0.35093054,231.01766,0.3182,72.194522,0.09727,303.21219,0.3182,0.78159626,13.90184,0.015030677,99.403411,0,0,1,,,,2.1887E-5,28.0693,279.16593,13.826555,0
6179166.63,,5905,14.6836,14.8691,0,9.3E-6,14.895925,0.32011565,189.29114,0.3039,56.364715,0.07022,245.65586,0.3039,0.42257505,12.870521,0.014552523,99.35969,0,0,1,,,,1.916E-5,27.80368,221.88859,12.707579,0
6179294.19,,5905,14.6997,14.8496,0,9.3E-6,14.892247,0.31120273,188.7345,0.2503,56.34291,0.07019,245.07741,0.2503,6.1262083,12.705932,0.012612749,99.438719,0,0,1,,,,1.9353E-5,25.74104,221.77902,12.673339,0
6179666.63,,5905,13.0548,13.237,0,9.3E-6,13.248294,0.28200529,154.42574,0.245,43.438532,0.05524,197.86427,0.245,0.62075401,11.898124,0.012901964,99.366236,0,0,1,,,,1.6695E-5,25.41186,175.5173,11.656273,0
6179771.39,,5905,13.0682,13.225,0,9.3E-6,13.251091,0.27777348,154.87021,0.2147,43.463472,0.05527,198.33368,0.2147,2.8725948,11.846248,0.012734311,99.370922,0,0,1,,,,1.6807E-5,23.79625,175.59142,11.687355,0
6180112.58,,5905,11.6034,11.7698,0,9.3E-6,11.778173,0.24814341,131.0938,0.2639,33.268615,0.04091,164.36242,0.2639,0.095821878,11.383375,0.012050747,99.343071,0,0,1,,,,1.45E-5,23.6925,138.72536,11.130232,0
6180213.73,,5905,11.6174,11.766,0,9.3E-6,11.78597,0.24752747,129.95881,0.1525,33.323038,0.04105,163.28184,0.1525,10.119775,11.179086,0.010202405,99.437293,0,0,1,,,,1.4658E-5,22.76675,138.9091,11.026568,0
6180551.59,,5905,10.3181,10.4811,0,9.3E-6,10.476576,0.21637929,114.212,0.1904,25.336628,0.03338,139.54862,0.1904,0.17826253,11.220239,0.011254425,99.323416,0,0,1,,,,1.2494E-5,22.35817,109.75863,10.901654,0
6180650.42,,5905,10.331,10.4743,0,9.3E-6,10.484715,0.22095927,114.04224,0.1496,25.382654,0.03334,139.4249,0.1496,3.5483448,11.030868,0.0097504981,99.405191,0,0,1,,,,1.269E-5,22.44048,109.92924,10.877,0
6181023.66,,5905,9.17841,9.3289,0,9.3E-6,9.3215067,0.18400004,107.48665,0.1823,19.164472,0.02926,126.65112,0.1823,0.1331919,11.734964,0.010723311,99.286173,0,0,1,,,,1.0849E-5,22.06174,86.890487,11.531038,0
6181125.8,,5905,9.18675,9.325,0,9.2E-6,9.3317976,0.19628149,107.46378,0.1092,19.216983,0.02937,126.68076,0.1092,1.0907734,11.604626,0.0086570786,99.418792,0,0,1,,,,1.0962E-5,23.46993,87.082446,11.515871,0
6181476.55,,5905,8.15922,8.306,0,9.3E-6,8.2862751,0.15285542,117.60747,0.1997,14.345852,0.02017,131.95332,0.1997,0.08877937,14.50581,0.0095877283,99.315116,0,0,1,,,,9.1464E-6,23.20925,68.662355,14.193044,0
6181596.97,,5905,8.16862,8.3035,0,9.3E-6,8.3061202,0.17833391,117.18291,0.1479,14.425607,0.02031,131.60852,0.1479,0.79432464,14.186504,0.01034086,99.249806,0,0,1,,,,9.3327E-6,29.01162,68.991633,14.10802,0
6181989.64,,5905,7.25725,7.3947,0,9.3E-6,7.3757773,0.13856276,122.8658,0.3335,10.681157,0.0149,133.54696,0.3335,0.24292218,16.652251,0.0062858234,99.48517,0,0,1,,,,8.0549E-6,28.37301,54.40209,16.658014,0
6182121.89,,5905,7.26522,7.3922,0,9.3E-6,7.3902224,0.15412803,124.97779,0.3279,10.731861,0.01498,135.70965,0.3279,4.6708068,16.506526,0.0064766807,99.459179,0,0,1,,,,8.2595E-6,33.3045,54.615387,16.911235,0
6182989.44,,5905,6.46006,6.6348,0,9.3E-6,6.6025079,0.13554857,69.569771,0.2132,8.0131161,0.01011,77.582887,0.2132,0.40449407,10.737895,0.0042623953,99.570281,0,0,1,,,,7.2502E-6,21.49662,43.59311,10.536871,0
6183086.5,,5905,6.46188,6.6391,0,9.3E-6,6.6035537,0.13747877,68.839035,0.2081,8.0192839,0.01012,76.858319,0.2081,1.2165392,10.791338,0.004080637,99.594367,0,0,1,,,,7.1455E-6,21.47579,43.606921,10.424544,0
6183479.42,,5905,5.73318,5.9052,0,9.3E-6,5.8735395,0.1436498,39.820845,0.2019,5.8576052,0.008177,45.67845,0.2017,0.73436058,7.5998429,0,100,0,0,1,,,,6.0104E-6,21.58268,34.498466,6.7797016,0
6183545.88,,5905,5.73793,5.9064,0,9.4E-6,5.8706203,0.12461259,39.585883,0.1211,5.8546654,0.008172,45.440548,0.1211,0.76604778,7.5535519,0.0061306357,99.274152,0,0,1,,,,6.0492E-6,15.19969,34.464182,6.7430495,0
6183960.64,,5905,5.09733,5.2554,0,9.3E-6,5.2217369,0.10989866,23.330416,0.06696,4.205399,0.005235,27.535815,0.06696,4.0595091,5.4143287,0.0017102497,99.755632,0,0,1,,,,5.0947E-6,10.32737,27.266537,4.4679417,0
6184015.72,,5905,5.10158,5.258,0,9.3E-6,5.2284277,0.10999224,23.533191,0.09502,4.2199357,0.005235,27.753126,0.09502,0.604126,5.1482262,0.0028933714,99.563263,0,0,1,,,,5.4078E-6,10.82866,27.336456,4.5010072,0
6184353.61,,5905,4.53089,4.6741,0,9.3E-6,4.6442802,0.11797033,13.702659,0.04601,2.9790837,0.00531,16.681742,0.04601,0.20367034,3.9142636,0.0013133313,99.771088,0,0,1,,,,4.2684E-6,10.29645,21.569339,2.9504375,0
6184400.48,,5905,4.5337,4.6751,0,9.2E-6,4.6424247,0.098716214,13.578855,0.04996,2.9773717,0.005306,16.556227,0.04996,0.19185949,3.4803432,0.0016511932,99.677976,0,0,1,,,,4.7674E-6,7.828527,21.552107,2.9249489,0
6184723.17,,5905,4.02681,4.1517,0,9.3E-6,4.1258191,0.096284763,8.7004844,0.03902,2.1105198,0.003183,10.811004,0.03902,3.0694983,2.7690556,0.0025066113,99.422831,0,0,1,,,,3.9189E-6,6.960686,17.022384,2.1087896,0
6184759.36,,5905,4.02762,4.1549,0,9.3E-6,4.1227065,0.086326179,8.4342451,0.04084,2.1082157,0.00318,10.542461,0.04084,0.081068257,2.6286127,0.0011485343,99.726678,0,0,1,,,,4.0177E-6,5.538111,16.996709,2.0458029,0
6185068.11,,5905,3.58108,3.6939,0,9.3E-6,3.6658484,0.085756341,5.7731344,0.0214,1.4891099,0.002384,7.2622443,0.0214,0.041372611,2.1805973,0.00094656578,99.733507,0,0,1,,,,3.336E-6,5.257225,13.438445,1.5748426,0
6185102.69,,5905,3.5835,3.6901,0,9.2E-6,3.6650773,0.079300887,5.5257176,0.01516,1.4894576,0.002385,7.0151751,0.01516,0.95513867,2.1280825,0.0019233303,99.458873,0,0,1,,,,3.3076E-6,4.361195,13.432791,1.5076674,0
6185400.61,,5905,3.18457,3.2784,0,9.3E-6,3.2602288,0.078018994,3.8588508,0.008943,1.0459248,0.001516,4.9047756,0.008943,0.15716195,1.6880257,0.00065280119,99.769367,0,0,1,,,,2.9098E-6,4.256165,10.629092,1.1836135,0
6185433.41,,5905,3.18674,3.2809,0,9.3E-6,3.2580092,0.068444541,3.8595142,0.0114,1.0449517,0.001514,4.9044659,0.0114,0.65297591,1.6841116,0.0020475666,99.273581,0,0,1,,,,2.9254E-6,3.376051,10.614624,1.1846235,0
6185686.03,,5905,2.83032,2.896,0,9.2E-6,2.891202,0.06974227,2.6995493,0.005372,0.72977418,0.001232,3.4293235,0.005372,0.39172011,1.3623597,0.0005691896,99.750447,0,0,1,,,,2.5211E-6,3.368223,8.3590489,0.93371177,0
6185717.48,,5905,2.83226,2.8993,0,9.3E-6,2.8914239,0.06042326,2.7385286,0.00779,0.72929678,0.001232,3.4678254,0.00779,0.52254599,1.3346094,0.0012776044,99.422751,0,0,1,,,,2.6078E-6,2.724719,8.3603322,0.9471211,0
6185922.19,,5905,2.51801,2.5666,0,9.2E-6,2.5664364,0.059358205,2.0494667,0.005106,0.51421129,0.0008312,2.563678,0.005106,0.13266887,1.162807,0.00086725943,99.534249,0,0,1,,,,2.2113E-6,2.669219,6.586596,0.79856516,0
6185951.66,,5905,2.51886,2.5667,0,9.3E-6,2.5665234,0.055722315,1.9871334,0.00401,0.51530585,0.0008344,2.5024392,0.00401,1.3281382,1.1203409,0.0013460591,99.263797,0,0,1,,,,2.2441E-6,2.325614,6.5870423,0.77425104,0
6186143.67,,5905,2.24193,2.2718,0,9.3E-6,2.28089,0.053908438,1.5280744,0.003356,0.36673803,0.0006452,1.8948124,0.003356,0.50736939,0.9882388,0.0012164063,99.209509,0,0,1,,,,1.9273E-6,2.240682,5.2024591,0.66994654,0
6186172.7,,5905,2.24313,2.2731,0,9.2E-6,2.2800617,0.050792266,1.5180012,0.003606,0.36640702,0.0006449,1.8844082,0.003606,0.25126701,1.0069237,0.0013321302,99.153206,0,0,1,,,,1.8818E-6,1.976478,5.1986816,0.66577198,0
6186365.47,,5905,1.99674,2.0098,0,9.3E-6,2.0274041,0.049866334,1.1659355,0.002406,0.26476532,0.0005219,1.4307008,0.002406,3.577365,0.8569206,0.00097246938,99.245625,0,0,1,,,,1.678E-6,2.013847,4.1103675,0.57508784,0
6186393.11,,5905,1.99723,2.0099,0,9.2E-6,2.0260039,0.045769189,1.1525912,0.002257,0.26437206,0.0005213,1.4169632,0.002257,0.45122107,0.84123787,0.001002056,99.213099,0,0,1,,,,1.6932E-6,1.713841,4.104692,0.56889877,0
6186697.83,,5905,1.99705,2.0105,0,9.3E-6,2.0280694,0.049772836,1.1587372,0.002346,0.26499524,0.0005223,1.4237324,0.002346,1.6472019,0.85104218,0.0010011536,99.221431,0,0,1,,,,1.6816E-6,2,4.1130657,0.57134984,0
6186725.7,,5905,1.99746,2.0109,0,9.3E-6,2.0262381,0.045735107,1.153308,0.002315,0.26447379,0.0005215,1.4177818,0.002315,16.878305,0.85086388,0.0011222121,99.128335,0,0,1,,,,1.676E-6,1.702084,4.1056409,0.56918678,0
6186910.41,,5905,2.21285,2.2408,0,9.3E-6,2.247788,0.046052025,1.4537526,0.002638,0.35186113,0.0006319,1.8056137,0.002638,0.98253242,0.94311943,0.0010335885,99.300025,0,0,1,,,,1.9233E-6,1.701728,5.0525508,0.64674808,0
6186938.91,,5905,2.21336,2.2419,0,9.3E-6,2.2502557,0.048765003,1.4630287,0.003299,0.35289377,0.000633,1.8159225,0.003299,0.13581926,0.94420245,0.0010330389,99.299725,0,0,1,,,,1.932E-6,1.886239,5.0636505,0.65016112,0
6187124.13,,5905,2.43049,2.473,0,9.3E-6,2.4720453,0.049207208,1.8314698,0.003911,0.4618048,0.0007184,2.2932746,0.003911,0.99643138,1.0873549,0.0015411068,99.116529,0,0,1,,,,2.121E-6,1.888405,6.1110078,0.74087227,0
6187153,,5905,2.43241,2.475,0,9.3E-6,2.4759404,0.053394422,1.8575657,0.004762,0.463969,0.0007215,2.3215347,0.004762,2.0842714,1.1097333,0.0017529688,99.009387,0,0,1,,,,2.1054E-6,2.17471,6.1302809,0.75024651,0
6187391.08,,5905,2.65032,2.7075,0,9.3E-6,2.6998698,0.054241397,2.2719465,0.004843,0.59795616,0.001086,2.8699026,0.004843,2.1475197,1.2291376,0.001541014,99.238403,0,0,1,,,,2.3461E-6,2.219467,7.2892971,0.84150222,0
6187420.61,,5905,2.65252,2.7103,0,9.3E-6,2.7032281,0.058175241,2.2554765,0.005658,0.60045219,0.001093,2.8559287,0.005658,2.4030393,1.231604,0.0015902528,99.220842,0,0,1,,,,2.3302E-6,2.458275,7.3074422,0.83436412,0
6187675.42,,5905,2.87041,2.9383,0,9.3E-6,2.9268175,0.057657042,2.7587645,0.0053,0.75689168,0.001221,3.5156562,0.0053,1.3303316,1.3575694,0.001511991,99.339723,0,0,1,,,,2.6003E-6,2.463208,8.5662607,0.94258166,0
6187706.7,,5905,2.87193,2.9418,0,9.2E-6,2.9308433,0.061297886,2.8198284,0.005524,0.75851412,0.00122,3.5783425,0.005524,2.2310689,1.3812863,0.00092753208,99.597608,0,0,1,,,,2.5971E-6,2.715139,8.5898427,0.96212185,0
6187972.61,,5905,3.08968,3.1694,0,9.3E-6,3.1529161,0.061424241,3.4725356,0.009486,0.94265532,0.001297,4.4151909,0.009486,0.1193012,1.5558427,0.0012374829,99.525794,0,0,1,,,,2.8462E-6,2.762573,9.9408799,1.1013727,0
6188004.27,,5905,3.09217,3.1721,0,9.3E-6,3.1567159,0.065548843,3.5399613,0.008208,0.94674038,0.001304,4.4867017,0.008208,0.42886385,1.6047437,0.0015138467,99.432569,0,0,1,,,,2.8058E-6,3.111685,9.9648554,1.1214064,0
6188272.45,,5905,3.30947,3.3996,0,9.3E-6,3.3774946,0.066647926,4.2468403,0.01115,1.1686001,0.001809,5.4154404,0.01115,3.7073013,1.7993944,0.0019882418,99.346054,0,0,1,,,,3.0218E-6,3.209487,11.40747,1.2573937,0
6188304.48,,5905,3.31152,3.4013,0,9.3E-6,3.3817245,0.071382556,4.2590349,0.0126,1.1736699,0.00182,5.4327047,0.0126,0.15877984,1.7949922,0.0021042143,99.306727,0,0,1,,,,3.0396E-6,3.598789,11.43606,1.2594269,0
6188572.14,,5905,3.52735,3.6257,0,9.2E-6,3.600244,0.069334009,5.3109441,0.01724,1.4150472,0.002266,6.7259913,0.01724,0.16324824,2.0749237,0.0025952777,99.245647,0,0,1,,,,3.2569E-6,3.589984,12.961757,1.4751623,0
6188605.81,,5905,3.52929,3.6268,0,9.3E-6,3.6064936,0.075746571,5.3607621,0.0135,1.4206918,0.002276,6.7814539,0.0135,1.4023131,2.0599794,0.0024208392,99.289104,0,0,1,,,,3.3067E-6,4.149847,13.006796,1.4864194,0
6188881.75,,5905,3.74716,3.8511,0,9.3E-6,3.8269602,0.074406163,6.581568,0.01726,1.6898663,0.002684,8.2714343,0.01726,0.52716983,2.3436515,0.0012379115,99.674797,0,0,1,,,,3.5366E-6,4.119959,14.645624,1.7197901,0
6188915.58,,5905,3.74954,3.8544,0,9.3E-6,3.8324745,0.080173588,6.6212396,0.01577,1.6978091,0.002695,8.3190488,0.01577,0.60491826,2.3276848,0.0010169944,99.73083,0,0,1,,,,3.5801E-6,4.687303,14.687861,1.727667,0
6189192.72,,5905,3.96705,4.0797,0,9.2E-6,4.0510701,0.078221069,8.0038202,0.02253,2.0028653,0.003057,10.006685,0.02253,0.10691825,2.6519746,0.0026059692,99.385124,0,0,1,,,,3.7882E-6,4.65537,16.411169,1.9757299,0
6189229.3,,5905,3.97036,4.083,0,9.3E-6,4.0576474,0.084614815,8.1747315,0.02226,2.0110969,0.003066,10.185828,0.02226,0.44997004,2.6746452,0.0019088073,99.549026,0,0,1,,,,3.8194E-6,5.303949,16.464502,2.0146481,0
6189503.72,,5905,4.18584,4.3006,0,9.3E-6,4.2770894,0.083057735,9.8636957,0.02465,2.3503749,0.003553,12.214071,0.02465,0.63316369,2.9823537,0.00049325745,99.893537,0,0,1,,,,4.0983E-6,5.34929,18.293493,2.3061701,0
6189540.86,,5905,4.19047,4.3078,0,9.3E-6,4.283224,0.088057011,10.069988,0.0242,2.3588768,0.003569,12.428865,0.0242,0.32891106,2.9958759,0.0015494293,99.663305,0,0,1,,,,4.1579E-6,5.964707,18.346008,2.3510299,0
6189814.98,,5905,4.40676,4.5304,0,9.4E-6,4.5027853,0.087405277,12.156982,0.04343,2.7274232,0.004601,14.884406,0.04343,0.72058558,3.4960088,0.00060322541,99.884665,0,0,1,,,,4.2608E-6,5.991752,20.275076,2.6998805,0
6189861.17,,5905,4.41143,4.5352,0,9.3E-6,4.5111573,0.094683122,12.408532,0.04399,2.7410714,0.004643,15.149604,0.04399,0.33894298,3.4875341,0.0018512697,99.641368,0,0,1,,,,4.3544E-6,6.992018,20.350541,2.7506316,0
6190137.89,,5905,4.62591,4.7574,0,9.3E-6,4.7280923,0.091527495,14.945554,0.06042,3.1402859,0.005623,18.08584,0.06042,0.74927842,3.9317703,0.0043697344,99.223194,0,0,1,,,,4.6245E-6,6.975068,22.354856,3.1610115,0
6190185.63,,5905,4.62967,4.7621,0,9.2E-6,4.7365141,0.099569664,14.918672,0.04899,3.1583616,0.005648,18.077034,0.04899,1.7667774,3.9569506,0.0040080999,99.295695,0,0,1,,,,4.5905E-6,7.863541,22.434566,3.1497156,0
6190465.59,,5905,4.84588,4.9831,0,9.3E-6,4.9559657,0.095413555,18.438005,0.06418,3.6069363,0.005658,22.044941,0.06418,0.33763915,4.5542074,0.0046750446,99.247585,0,0,1,,,,4.8663E-6,7.913901,24.561596,3.7203657,0
6190517.25,,5905,4.85102,4.9913,0,9.3E-6,4.9656762,0.10478674,18.457139,0.05408,3.6272108,0.005641,22.08435,0.05408,0.90632712,4.5260438,0.0037054353,99.402149,0,0,1,,,,4.8999E-6,9.108415,24.65794,3.7169437,0
6190805.84,,5905,5.06732,5.2118,0,9.3E-6,5.1813384,0.10088378,22.202023,0.0681,4.1107695,0.005254,26.312792,0.0681,1.9222511,5.1242641,0.0025318817,99.624573,0,0,1,,,,5.1487E-6,9.052088,26.846268,4.2849976,0
6190860.53,,5905,5.07174,5.2191,0,9.2E-6,5.1905599,0.10933505,22.515712,0.06077,4.1315984,0.005247,26.64731,0.06077,1.0872973,5.1496587,0.00097462334,99.855446,0,0,1,,,,5.1799E-6,10.24853,26.941912,4.3378195,0
6191147.33,,5905,5.28599,5.4362,0,9.2E-6,5.4027943,0.10503354,26.843897,0.09855,4.6381534,0.005629,31.48205,0.09855,0.40901481,5.8562687,0.0063331068,99.135718,0,0,1,,,,5.4099E-6,10.29932,29.190187,4.9685209,0
6191205.3,,5905,5.29081,5.4404,0,9.3E-6,5.4141028,0.11425652,27.006359,0.06842,4.664797,0.005675,31.671156,0.06842,1.9174714,5.7266892,0.0027755786,99.613415,0,0,1,,,,5.5461E-6,11.71254,29.312509,4.9881504,0
6191514.47,,5905,5.50725,5.6616,0,9.2E-6,5.6267973,0.10881928,32.10244,0.08365,5.2038806,0.00684,37.30632,0.08365,0.73133902,6.5992381,0.0046766399,99.407913,0,0,1,,,,5.6781E-6,11.45338,31.660848,5.7052775,0
6191575.89,,5905,5.51371,5.6729,0,9.3E-6,5.6381555,0.11845799,32.736345,0.1009,5.2303998,0.006903,37.966745,0.1009,3.6992539,6.4988936,0.00070326242,99.908859,0,0,1,,,,5.846E-6,13.19848,31.788797,5.8062153,0
6191902.31,,5905,5.72893,5.8863,0,9.3E-6,5.8511167,0.11218179,38.79121,0.133,5.801991,0.00809,44.593201,0.133,0.4704929,7.4381671,0.0058235957,99.305755,0,0,1,,,,6.0269E-6,12.99779,34.235567,6.6297105,0
6191979.14,,5905,5.73608,5.8948,0,9.3E-6,5.8629018,0.1237665,38.859696,0.1427,5.8328176,0.008139,44.692513,0.1427,1.1622301,7.4026786,0.0070724898,99.154381,0,0,1,,,,6.0763E-6,14.87633,34.373618,6.6280652,0
6192330.92,,5905,5.95245,6.1116,0,9.3E-6,6.0761343,0.11726045,46.412871,0.14,6.4285867,0.008771,52.841457,0.14,0.36406555,8.4095598,0.0050247401,99.439124,0,0,1,,,,6.3109E-6,14.80536,36.919408,7.6385524,0
6192415.73,,5905,5.95747,6.1161,0,9.3E-6,6.0877642,0.12789087,46.735061,0.1866,6.4602235,0.008794,53.195284,0.1866,3.6828674,8.3292709,0.0052124159,99.411581,0,0,1,,,,6.4157E-6,16.81912,37.060873,7.6768842,0
6192762.78,,5905,6.17112,6.3301,0,9.2E-6,6.2987858,0.12229649,54.557344,0.1704,7.0777266,0.009173,61.635071,0.1704,0.59910241,9.3404168,0.0039837695,99.579392,0,0,1,,,,6.6206E-6,16.65854,39.674702,8.6615653,0
6192851.52,,5905,6.17725,6.3368,0,9.3E-6,6.3105656,0.13302371,54.98455,0.1533,7.111973,0.009195,62.096523,0.1533,3.7115335,9.3130115,0.0047419213,99.49648,0,0,1,,,,6.6942E-6,18.68083,39.823238,8.7130938,0
6193149.75,,5905,6.38733,6.5487,0,9.3E-6,6.5158446,0.12728094,64.449476,0.2343,7.7438511,0.009747,72.193327,0.2343,0.59014251,10.819682,0.009021086,99.124734,0,0,1,,,,6.7194E-6,18.62602,42.45623,9.891193,0
6193247.17,,5905,6.39517,6.5601,0,9.3E-6,6.5324477,0.13895187,65.562744,0.2473,7.7918876,0.009805,73.354632,0.2473,1.1552542,10.506812,0.0049438478,99.502897,0,0,1,,,,7.0095E-6,21.63936,42.672873,10.036474,0
6193628.17,,5905,6.61423,6.7858,0,9.3E-6,6.7460017,0.12924775,77.34172,0.2446,8.4802193,0.0109,85.821939,0.2446,2.9320832,11.865685,0.0053282871,99.494118,0,0,1,,,,7.2627E-6,21.01362,45.508539,11.464824,0
6193731.73,,5905,6.61995,6.7895,0,9.3E-6,6.7589195,0.14196492,77.625449,0.2302,8.5208062,0.01097,86.146255,0.2302,3.8330791,11.801553,0.0054035186,99.484618,0,0,1,,,,7.3303E-6,23.73137,45.682992,11.48489,0
6194137.11,,5905,6.83546,7.009,0,9.2E-6,6.9697859,0.13343773,91.410053,0.3164,9.229906,0.01237,100.63996,0.3164,4.9595488,13.419522,0.0063216044,99.432389,0,0,1,,,,7.5349E-6,23.60311,48.577916,13.115188,0
6194249.95,,5905,6.84084,7.0168,0,9.3E-6,6.9828365,0.14692539,91.914836,0.2762,9.273296,0.01245,101.18813,0.2762,2.6704797,13.32715,0.0045609117,99.587786,0,0,1,,,,7.6186E-6,26.83904,48.760006,13.162965,0
6194673.63,,5905,7.05834,7.237,0,9.3E-6,7.193502,0.13773761,108.27599,0.3633,10.017096,0.01386,118.29309,0.3633,2.460914,15.412446,0.0099616345,99.161346,0,0,1,,,,7.7296E-6,26.6543,51.746471,15.051917,0
6194797.56,,5905,7.06321,7.2443,0,9.3E-6,7.2079422,0.15241222,109.83172,0.3884,10.066177,0.01395,119.8979,0.3884,5.0771475,15.22368,0.0067201266,99.423772,0,0,1,,,,7.9141E-6,30.82489,51.95443,15.237598,0
6195238.28,,5905,7.27883,7.4607,0,9.3E-6,7.4178655,0.14360911,126.87172,0.3822,10.838221,0.01512,137.70994,0.3822,0.48651547,17.141667,0.0079422105,99.358124,0,0,1,,,,8.0777E-6,30.44736,55.024729,17.103535,0
6195373.67,,5905,7.28325,7.4675,0,9.3E-6,7.4313191,0.15645347,128.33584,0.3559,10.885721,0.01519,139.22156,0.3559,7.7244559,16.908795,0.0055321864,99.544613,0,0,1,,,,8.2657E-6,34.28333,55.224504,17.269591,0
6195829.39,,5905,7.49933,7.6816,0,9.2E-6,7.6428907,0.15270205,139.3806,0.2606,11.699612,0.01624,151.08021,0.2606,0.16493859,18.248209,0.0087476001,99.325817,0,0,1,,,,8.327E-6,33.81759,58.413778,18.236634,0
6195971.73,,5905,7.50456,7.6872,0,9.3E-6,7.6543417,0.16353096,138.64035,0.2066,11.741694,0.01629,150.38205,0.2066,0.24560557,17.804325,0.0072759085,99.430001,0,0,1,,,,8.4875E-6,36.49642,58.588947,18.112642,0
6196432.88,,5905,7.72114,7.9038,0,9.3E-6,7.8705285,0.16770419,135.52932,0.2237,12.603502,0.01741,148.13282,0.2237,0.4938659,17.433579,0.012078901,99.104508,0,0,1,,,,8.5613E-6,35.60865,61.945218,17.21985,0
6196569.27,,5905,7.72508,7.9057,0,9.2E-6,7.8783398,0.17043597,135.14184,0.166,12.636304,0.01745,147.77814,0.166,2.1063799,17.048682,0.0086469893,99.348523,0,0,1,,,,8.7156E-6,34.86716,62.068238,17.153594,0
6197022.25,,5905,7.93937,8.1222,0,9.2E-6,8.0960725,0.17936178,124.63138,0.2153,13.529694,0.01877,138.16108,0.2153,0.19100155,15.624519,0.010453159,99.238997,0,0,1,,,,8.8978E-6,34.09736,65.54639,15.394055,0
6197148.5,,5905,7.94555,8.1328,0,9.2E-6,8.0992132,0.1728171,124.74954,0.1714,13.545962,0.0188,138.2955,0.1714,7.0698802,15.397994,0.0097038896,99.283502,0,0,1,,,,9.0342E-6,31.24904,65.597254,15.402674,0
6197580.41,,5905,8.15959,8.3502,0,9.4E-6,8.3161839,0.18120422,116.75891,0.1819,14.46875,0.02039,131.22766,0.1819,0.21300358,14.374833,0.012072196,99.139576,0,0,1,,,,9.1918E-6,30.79599,69.158915,14.039963,0
6197698.22,,5905,8.16346,8.3514,0,9.3E-6,8.3222145,0.1788099,116.78551,0.1305,14.496749,0.02044,131.28226,0.1305,0.21245204,14.056695,0.0067444819,99.510149,0,0,1,,,,9.3759E-6,28.74967,69.259255,14.032985,0
6198092.84,,5905,8.37699,8.5679,0,9.3E-6,8.5362316,0.18387045,112.28237,0.2009,15.43527,0.02217,127.71764,0.2009,0.095150086,13.474625,0.011197846,99.214453,0,0,1,,,,9.5364E-6,28.11339,72.86725,13.153623,0
6198205.56,,5905,8.38181,8.5741,0,9.3E-6,8.5436834,0.18241839,112.30439,0.1223,15.468272,0.02224,127.77266,0.1223,0.69858671,13.137593,0.0070573341,99.493747,0,0,1,,,,9.764E-6,26.94925,72.994526,13.144727,0
6198574.27,,5905,8.59551,8.7901,0,9.3E-6,8.7541612,0.18431703,109.77255,0.1945,16.426,0.02403,126.19855,0.1945,0.19353843,12.921134,0.012803352,99.120802,0,0,1,,,,9.8324E-6,26.27519,76.635338,12.539471,0
6198684.94,,5905,8.60294,8.7994,0,9.2E-6,8.7642978,0.18809984,109.03935,0.1003,16.472668,0.02411,125.51202,0.1003,0.94443506,12.683336,0.01123151,99.220224,0,0,1,,,,9.9546E-6,25.84227,76.812917,12.44131,0
6199088.98,,5905,8.81916,9.0142,0,9.3E-6,8.9810825,0.18932756,108.07582,0.1587,17.49033,0.02594,125.56615,0.1587,0.2264004,12.30113,0.0082687023,99.437794,0,0,1,,,,1.025E-5,25.36667,80.659842,12.033718,0
6199194.52,,5905,8.82444,9.0203,0,9.3E-6,8.987779,0.18959689,107.94726,0.1307,17.525867,0.026,125.47312,0.1307,0.38458362,12.197533,0.010710574,99.266677,0,0,1,,,,1.0343E-5,24.60226,80.780172,12.010449,0
6199574.73,,5905,9.03771,9.2343,0,9.3E-6,9.2008734,0.19245826,108.0055,0.1799,18.561402,0.02802,126.5669,0.1799,0.098595155,12.007286,0.010212889,99.318209,0,0,1,,,,1.0594E-5,24.39507,84.65607,11.738614,0
6199679.69,,5905,9.0438,9.24,0,9.2E-6,9.2084979,0.19361631,108.0337,0.1231,18.598361,0.0281,126.63206,0.1231,0.94659572,11.869921,0.0088166417,99.405579,0,0,1,,,,1.0715E-5,24.01457,84.796434,11.731957,0
6200032.98,,5905,9.2551,9.4538,0,9.3E-6,9.4193838,0.19669977,108.06729,0.1951,19.658818,0.03026,127.7261,0.1951,0.20944642,11.821582,0.01344834,99.123069,0,0,1,,,,1.0873E-5,23.73984,88.724792,11.472862,0
6200136.81,,5905,9.26196,9.4566,0,9.3E-6,9.4300343,0.20055628,107.88994,0.1433,19.713869,0.03037,127.60381,0.1433,0.94192511,11.741749,0.010909758,99.286487,0,0,1,,,,1.0923E-5,23.64316,88.925547,11.441097,0
6200498.45,,5905,9.4773,9.6759,0,9.3E-6,9.6437204,0.20100929,108.54177,0.1921,20.81991,0.0324,129.36168,0.1921,0.22416075,11.584484,0.011922853,99.235444,0,0,1,,,,1.1227E-5,23.4835,93.001344,11.255176,0
6200601.42,,5905,9.48402,9.6788,0,9.3E-6,9.6529174,0.20371999,108.75933,0.1563,20.868357,0.03248,129.62769,0.1563,2.5907367,11.478278,0.011459896,99.258566,0,0,1,,,,1.1353E-5,23.16897,93.178815,11.266991,0
6200944.7,,5905,9.6961,9.8948,0,9.4E-6,9.8621511,0.20495274,109.18597,0.2109,21.972521,0.03398,131.15849,0.2109,0.10188855,11.447463,0.010610053,99.33368,0,0,1,,,,1.1511E-5,22.95656,97.262024,11.071213,0
6201045.84,,5905,9.70361,9.8997,0,9.3E-6,9.8736929,0.20934861,109.98188,0.2022,22.03693,0.03405,132.01881,0.2022,0.27090089,11.467466,0.012313097,99.225502,0,0,1,,,,1.1575E-5,22.89493,97.489811,11.13888,0
6201692.55,,5905,9.94385,10.0513,0,9.3E-6,10.077579,0.20910104,110.50355,0.1432,23.126451,0.03469,133.63001,0.1432,0.30808046,10.982045,0.0083924069,99.464958,0,0,1,,,,1.2213E-5,22.93493,101.55759,10.965288,0
6201805.61,,5905,9.94162,10.0385,0,9.3E-6,10.069184,0.20717569,110.56362,0.143,23.084529,0.03468,133.64815,0.143,0.38547689,10.947127,0.0073806956,99.527336,0,0,1,,,,1.2248E-5,21.96409,101.38847,10.980395,0
6202050.08,,5905,10.139,10.2311,0,9.3E-6,10.256272,0.20838055,112.3346,0.1824,24.108977,0.03439,136.44358,0.1824,0.6260731,11.263123,0.011556524,99.292889,0,0,1,,,,1.2173E-5,21.89425,105.19112,10.952771,0
6202149.14,,5905,10.1454,10.2364,0,9.3E-6,10.26835,0.21710259,112.37815,0.1536,24.179297,0.03434,136.55745,0.1536,3.1361737,11.173431,0.010816969,99.33402,0,0,1,,,,1.2277E-5,22.52625,105.43901,10.944129,0
6202398.45,,5905,10.3575,10.4516,0,9.4E-6,10.478526,0.21599422,114.30435,0.1926,25.347252,0.03337,139.6516,0.1926,0.23732881,11.19898,0.011736707,99.292832,0,0,1,,,,1.253E-5,22.34686,109.7995,10.908438,0
6202499.52,,5905,10.3646,10.4581,0,9.4E-6,10.488436,0.21924219,114.13199,0.1574,25.403558,0.03332,139.53555,0.1574,2.3446055,11.095627,0.010932513,99.336836,0,0,1,,,,1.2632E-5,22.39796,110.00728,10.881698,0
6202746.98,,5905,10.5785,10.6759,0,9.3E-6,10.700626,0.22007154,116.3512,0.218,26.613051,0.03229,142.96426,0.218,0.32817433,11.208126,0.012949358,99.235464,0,0,1,,,,1.2821E-5,22.19125,114.50339,10.873309,0
6202846.25,,5905,10.5844,10.6826,0,9.3E-6,10.711333,0.22485583,116.37075,0.1736,26.675672,0.03225,143.04642,0.1736,1.6562559,11.078825,0.010827507,99.354424,0,0,1,,,,1.2967E-5,22.41625,114.73265,10.864264,0
6203092.27,,5905,10.7971,10.8995,0,9.3E-6,10.925154,0.2250925,119.02829,0.1973,27.927271,0.03184,146.95556,0.1973,0.2012209,11.200669,0.012241843,99.288338,0,0,1,,,,1.3182E-5,22.15765,119.35899,10.894884,0
6203192.23,,5905,10.8029,10.9138,0,9.3E-6,10.937918,0.23067399,119.19848,0.2018,28.006787,0.03185,147.20527,0.2018,0.15646668,11.23345,0.012283839,99.288609,0,0,1,,,,1.3166E-5,22.40134,119.63804,10.897731,0
6203440.2,,5905,11.0204,11.1206,0,9.3E-6,11.1492,0.23027147,121.52048,0.1862,29.278663,0.03272,150.79914,0.1862,0.60203781,11.200889,0.012633521,99.27753,0,0,1,,,,1.3527E-5,22.4669,124.30465,10.89948,0
6203539.28,,5905,11.0269,11.1249,0,9.2E-6,11.159613,0.23535108,121.56639,0.1572,29.344665,0.0328,150.91105,0.1572,7.8333904,11.143086,0.011927359,99.315244,0,0,1,,,,1.3604E-5,22.40178,124.53697,10.893423,0
6203783.72,,5905,11.2395,11.3348,0,9.2E-6,11.368054,0.23340766,124.64314,0.2075,30.638671,0.0349,155.28181,0.2075,0.20698303,11.305802,0.013699262,99.233213,0,0,1,,,,1.3803E-5,22.28617,129.23265,10.964334,0
6203884.27,,5905,11.2464,11.3406,0,9.2E-6,11.379341,0.23887349,124.41195,0.1446,30.70359,0.03503,155.11554,0.1446,5.278684,11.131991,0.01150646,99.347695,0,0,1,,,,1.3993E-5,22.6116,129.48941,10.933141,0
6204129.88,,5905,11.4609,11.5535,0,9.3E-6,11.591492,0.23805427,127.426,0.2058,32.062858,0.038,159.48885,0.2058,0.37389733,11.296849,0.013368507,99.26171,0,0,1,,,,1.4185E-5,22.26398,134.36269,10.993063,0
6204230.81,,5905,11.4674,11.5592,0,9.3E-6,11.601976,0.24364508,127.4465,0.1581,32.124658,0.03815,159.57115,0.1581,14.037084,11.167462,0.011073989,99.382209,0,0,1,,,,1.4346E-5,22.5937,134.60584,10.984896,0
6204476.42,,5905,11.6813,11.7726,0,9.3E-6,11.81228,0.24080488,130.68122,0.2026,33.502181,0.04148,164.1834,0.2026,0.57969469,11.380442,0.013732555,99.255539,0,0,1,,,,1.4495E-5,22.33492,139.52996,11.063166,0
6204577.63,,5905,11.6868,11.7786,0,9.4E-6,11.824563,0.24798025,130.84613,0.1558,33.577581,0.04167,164.42371,0.1558,6.7313914,11.224914,0.011004592,99.395748,0,0,1,,,,1.4705E-5,22.76088,139.82029,11.065621,0
6204824.33,,5905,11.9013,11.992,0,9.4E-6,12.034445,0.24512655,133.93898,0.2103,34.978278,0.04495,168.91726,0.2103,0.4692063,11.415625,0.013374019,99.285147,0,0,1,,,,1.4864E-5,22.44983,144.82786,11.129635,0
6204925.55,,5905,11.9076,11.9972,0,9.3E-6,12.046192,0.25314623,134.07738,0.1656,35.053595,0.04512,169.13097,0.1656,7.4473673,11.353486,0.012169995,99.34648,0,0,1,,,,1.4958E-5,22.83125,145.11075,11.13027,0
6205171.97,,5905,12.1225,12.2127,0,9.3E-6,12.258341,0.25083024,137.63864,0.2202,36.483902,0.04794,174.12254,0.2202,0.49482598,11.530271,0.013419973,99.296027,0,0,1,,,,1.5168E-5,22.70697,150.26694,11.228162,0
6205273.28,,5905,12.1283,12.2174,0,9.4E-6,12.269464,0.25701971,137.68505,0.1888,36.561537,0.04807,174.24659,0.1888,12.042917,11.402277,0.01269905,99.327124,0,0,1,,,,1.5346E-5,23.06054,150.53975,11.221766,0
6205523.36,,5905,12.3422,12.4327,0,9.3E-6,12.480077,0.254987,141.32861,0.2297,38.001313,0.05012,179.32992,0.2297,0.54899278,11.616248,0.014370731,99.257863,0,0,1,,,,1.551E-5,22.80455,155.75232,11.324338,0
6205625.94,,5905,12.349,12.4383,0,9.3E-6,12.491677,0.26158741,141.20104,0.1845,38.083244,0.05023,179.28428,0.1845,8.2039484,11.490081,0.01239282,99.35428,0,0,1,,,,1.5666E-5,23.2325,156.042,11.30361,0
6205874.48,,5905,12.5623,12.6539,0,9.3E-6,12.701384,0.25959357,144.70178,0.2347,39.537793,0.05184,184.23957,0.2347,0.38292738,11.682221,0.013998319,99.28786,0,0,1,,,,1.5841E-5,22.98016,161.32515,11.392599,0
6205978.09,,5905,12.5688,12.6576,0,9.3E-6,12.712153,0.26595758,144.99483,0.1907,39.616109,0.05192,184.61093,0.1907,11.032743,11.610084,0.012840757,99.342761,0,0,1,,,,1.5966E-5,23.36444,161.59884,11.406,0
6206227.78,,5905,12.783,12.8739,0,9.3E-6,12.923307,0.26352087,148.84083,0.2377,41.104409,0.05329,189.94524,0.2377,0.4986436,11.811891,0.014910841,99.254271,0,0,1,,,,1.6155E-5,23.22017,167.01187,11.51724,0
6206331.98,,5905,12.7899,12.8802,0,9.3E-6,12.935503,0.27157813,149.04208,0.2053,41.187159,0.05336,190.22924,0.2053,3.526266,11.751366,0.013316888,99.330931,0,0,1,,,,1.6255E-5,23.62378,167.32724,11.521939,0
6206580.2,,5905,13.0032,13.0988,0,9.2E-6,13.145976,0.26944521,152.7962,0.2564,42.704759,0.05463,195.50096,0.2564,0.40680398,11.918217,0.014767765,99.273015,0,0,1,,,,1.6477E-5,23.50273,172.81668,11.62304,0
6206684.66,,5905,13.0094,13.1035,0,9.2E-6,13.157294,0.27551979,153.00374,0.2134,42.78056,0.05469,195.7843,0.2134,8.4243959,11.823192,0.013239103,99.343291,0,0,1,,,,1.6626E-5,23.83643,173.11438,11.628815,0
6206935.91,,5905,13.2194,13.327,0,9.3E-6,13.368547,0.2735595,157.09674,0.2967,44.326114,0.05602,201.42285,0.2967,0.25883215,12.100852,0.015833915,99.236348,0,0,1,,,,1.6723E-5,23.64638,178.71804,11.75122,0
6207040.94,,5905,13.2276,13.3341,0,9.3E-6,13.383077,0.28137282,157.37544,0.2199,44.436388,0.05611,201.81183,0.2199,9.860773,11.97486,0.013837859,99.326,0,0,1,,,,1.6923E-5,24.2017,179.10674,11.759287,0
6207292.09,,5905,13.4418,13.5526,0,9.3E-6,13.594366,0.27878054,161.71153,0.3115,46.012461,0.05765,207.72399,0.3115,0.23116455,12.21283,0.016039727,99.237123,0,0,1,,,,1.7088E-5,23.94972,184.80678,11.895482,0
6207398.25,,5905,13.4506,13.5577,0,9.3E-6,13.608465,0.28672237,161.68571,0.2317,46.121179,0.05777,207.80689,0.2317,11.988936,12.056606,0.013381871,99.356366,0,0,1,,,,1.7304E-5,24.42566,185.19033,11.881259,0
6207648.78,,5905,13.6618,13.7737,0,9.3E-6,13.816711,0.28225103,166.26327,0.3032,47.706947,0.05955,213.97022,0.3032,0.30317164,12.315858,0.016008888,99.248522,0,0,1,,,,1.7453E-5,24.11321,190.90151,12.033491,0
6207755.05,,5905,13.6688,13.7812,0,9.3E-6,13.829848,0.2902861,166.45354,0.2394,47.81189,0.05967,214.26543,0.2394,1.6887924,12.213489,0.013960823,99.339686,0,0,1,,,,1.7614E-5,24.63172,191.26471,12.035818,0
6208005.84,,5905,13.8811,13.994,0,9.3E-6,14.039018,0.28783192,170.87069,0.3092,49.439685,0.06154,220.31038,0.3092,0.29760553,12.463699,0.016393277,99.24312,0,0,1,,,,1.7757E-5,24.42698,197.09402,12.171129,0
6208113.17,,5905,13.8895,14.0024,0,9.3E-6,14.052931,0.29566281,171.04543,0.2424,49.542736,0.06166,220.58817,0.2424,7.437395,12.338995,0.014450691,99.326582,0,0,1,,,,1.795E-5,24.9274,197.48487,12.171513,0
6208364.97,,5905,14.103,14.2157,0,9.3E-6,14.262232,0.29329796,175.33392,0.3321,51.201965,0.06362,226.53589,0.3321,0.21349474,12.561873,0.016424778,99.251445,0,0,1,,,,1.8115E-5,24.67799,203.41127,12.293582,0
6208472.94,,5905,14.1112,14.2227,0,9.3E-6,14.276459,0.30133346,175.85755,0.2586,51.320555,0.06376,227.17811,0.2586,11.114781,12.510414,0.014784151,99.323295,0,0,1,,,,1.8233E-5,25.12375,203.81728,12.318009,0
6208725.47,,5905,14.3225,14.4346,0,9.3E-6,14.483839,0.29674723,180.32583,0.3253,52.990172,0.06581,233.316,0.3253,0.31187516,12.71464,0.016676246,99.251699,0,0,1,,,,1.8433E-5,25.02083,209.78158,12.450141,0
6208834.58,,5905,14.33,14.4415,0,9.2E-6,14.497781,0.30458531,180.49413,0.2564,53.106756,0.06595,233.60089,0.2564,10.041952,12.588552,0.014795588,99.330011,0,0,1,,,,1.8631E-5,25.42928,210.18565,12.449777,0
6209087.16,,5905,14.5431,14.6532,0,9.2E-6,14.705349,0.30237163,185.12396,0.3362,54.806366,0.06813,239.93033,0.3362,0.40295975,12.869058,0.017480903,99.228125,0,0,1,,,,1.873E-5,25.1771,216.24727,12.588886,0
6209198.11,,5905,14.5517,14.6596,0,9.2E-6,14.719443,0.30990254,185.32284,0.2646,54.91439,0.06827,240.23723,0.2646,7.6806342,12.707239,0.014553408,99.349681,0,0,1,,,,1.8979E-5,25.73812,216.66199,12.590344,0
6209451.63,,5905,14.7652,14.8719,0,9.3E-6,14.928191,0.30588612,189.96796,0.3443,56.654397,0.07063,246.62236,0.3443,0.38126149,12.988168,0.017133272,99.253445,0,0,1,,,,1.9073E-5,25.41448,222.85089,12.725451,0
6209562.48,,5905,14.7725,14.8781,0,9.3E-6,14.942539,0.31586277,190.1437,0.2753,56.769247,0.07078,246.91295,0.2753,10.304745,12.881618,0.015139857,99.335352,0,0,1,,,,1.9244E-5,25.97634,223.27948,12.724992,0
6209817.86,,5905,14.984,15.0908,0,9.3E-6,15.149893,0.3115546,195.183,0.335,58.506675,0.07328,253.68967,0.335,0.71463583,13.1656,0.01797272,99.229521,0,0,1,,,,1.9358E-5,25.76324,229.51926,12.883457,0
6209929.69,,5905,14.9927,15.0968,0,9.3E-6,15.164151,0.31915085,195.21941,0.2794,58.628307,0.07346,253.84772,0.2794,2.2043789,12.986763,0.014626304,99.365161,0,0,1,,,,1.9621E-5,26.3312,229.95149,12.873744,0
6210605.39,,5905,15.023,15.1401,0,9.3E-6,15.204275,0.31513797,195.711,0.3094,58.965266,0.07396,254.67626,0.3094,0.19786722,12.675532,0.010309473,99.54249,0,0,1,,,,2.0147E-5,25.56666,231.16999,12.872103,0
6210731.06,,5905,15.0128,15.1258,0,9.3E-6,15.189197,0.31345985,195.40425,0.2972,58.840401,0.07377,254.24465,0.2972,0.35042439,12.828705,0.011655139,99.488745,0,0,1,,,,1.9879E-5,25.35106,230.71171,12.864686,0
6211017.77,,5905,16.54,16.6463,0,9.2E-6,16.712588,0.32988837,231.05598,0.3942,72.255941,0.09737,303.31192,0.3942,0.43810311,14.139961,0.019885735,99.224044,0,0,1,,,,2.1548E-5,25.65741,279.3106,13.825266,0
6211135.14,,5905,16.5466,16.6499,0,9.3E-6,16.732669,0.35381496,231.83343,0.3154,72.421507,0.09765,304.25494,0.3154,2.6644055,13.962928,0.015798263,99.375531,0,0,1,,,,2.187E-5,28.27992,279.9822,13.855138,0
6211486.38,,5905,18.0849,18.2404,0,9.3E-6,18.285814,0.36549895,269.31975,0.5333,87.161516,0.1177,356.48127,0.5333,0.25376004,15.301211,0.023224005,99.177354,0,0,1,,,,2.3408E-5,27.92586,334.37099,14.728344,0
6211610.55,,5905,18.0993,18.2409,0,9.3E-6,18.313833,0.39120751,269.91481,0.3634,87.427819,0.1181,357.34263,0.3634,10.009499,15.009086,0.017139214,99.381531,0,0,1,,,,2.3893E-5,30.60242,335.39647,14.738303,0
6211913.58,,5905,19.6288,19.7696,0,9.3E-6,19.828388,0.39968575,310.70036,0.5958,102.96154,0.1435,413.6619,0.5958,0.70721299,16.475646,0.028758209,99.065166,0,0,1,,,,2.5241E-5,30.01817,393.16498,15.669471,0
6212044.06,,5905,19.6406,19.7939,0,9.3E-6,19.867669,0.42763267,311.87173,0.5083,103.37316,0.1442,415.24489,0.5083,1.070561,16.261032,0.023797223,99.216475,0,0,1,,,,2.565E-5,32.95129,394.72425,15.69745,0
6212352.03,,5905,21.1933,21.3057,0,9.3E-6,21.40001,0.43441847,354.80048,0.5658,119.96032,0.1709,474.7608,0.5658,0.78592736,17.396309,0.027634955,99.157881,0,0,1,,,,2.7421E-5,32.52206,457.96044,16.579454,0
6212489.02,,5905,21.2019,21.3128,0,9.3E-6,21.425305,0.45758728,355.23142,0.4925,120.22497,0.1712,475.45639,0.4925,2.0187916,17.154777,0.022427714,99.30741,0,0,1,,,,2.7824E-5,34.79262,459.04368,16.579994,0
6212805.31,,5905,22.7429,22.8916,0,9.3E-6,22.972973,0.46405488,400.77643,0.7721,137.61366,0.1932,538.3901,0.7721,0.17273088,18.616734,0.030525546,99.137394,0,0,1,,,,2.9059E-5,34.30955,527.7575,17.445562,0
6212950.06,,5905,22.7589,22.8889,0,9.3E-6,23.004359,0.49216353,401.31271,0.5019,137.94608,0.1937,539.25879,0.5019,1.1081352,18.212578,0.021630658,99.375689,0,0,1,,,,2.9712E-5,37.23347,529.20053,17.445073,0
6213272.56,,5905,24.3001,24.4125,0,9.4E-6,24.528767,0.49605836,445.47427,0.6353,156.117,0.2271,601.59127,0.6353,0.68268854,19.462943,0.02931102,99.215676,0,0,1,,,,3.1044E-5,36.42516,601.66042,18.161299,0
6213446.66,,5905,24.3082,24.4137,0,9.3E-6,24.550139,0.52153378,445.96222,0.5511,156.36945,0.2276,602.33167,0.5511,4.4709773,19.277299,0.02649999,99.284299,0,0,1,,,,3.1369E-5,38.92589,602.70934,18.165364,0
6213819.17,,5905,25.8591,26.0143,0,9.2E-6,26.117026,0.52884245,493.0388,0.9545,176.02846,0.2715,669.06726,0.9545,0.19712063,20.749474,0.037125214,99.076363,0,0,1,,,,3.2409E-5,38.5546,682.09905,18.878061,0
6214000.31,,5905,25.8685,25.9956,0,9.2E-6,26.137791,0.55824146,492.74998,0.613,176.25159,0.2721,669.00157,0.613,0.29137841,20.120086,0.022333517,99.427678,0,0,1,,,,3.3354E-5,41.49895,683.18413,18.852013,0
6214390.3,,5905,27.419,27.5623,0,9.3E-6,27.688695,0.55608167,538.09215,0.9157,196.74562,0.331,734.83777,0.9157,0.15529766,21.451994,0.033149614,99.211333,0,0,1,,,,3.4401E-5,40.24017,766.66383,19.433641,0
6214576.8,,5905,27.4193,27.5435,0,9.2E-6,27.697509,0.58651648,538.06001,0.7315,196.83575,0.3313,734.89575,0.7315,0.25434553,21.133337,0.027858887,99.327437,0,0,1,,,,3.4901E-5,42.90399,767.15202,19.426296,0
6214979.98,,5905,28.9769,29.1103,0,9.2E-6,29.258409,0.58821736,584.60645,0.9195,218.04478,0.3644,802.65122,0.9195,0.14462395,22.247181,0.030931891,99.296972,0,0,1,,,,3.6214E-5,42.26667,856.05447,19.980801,0
6215174.94,,5905,28.9746,29.0948,0,9.3E-6,29.25788,0.61388582,586.46598,0.792,218.02854,0.3644,804.49453,0.792,0.15097977,22.089656,0.028742583,99.341105,0,0,1,,,,3.6548E-5,44.49436,856.02355,20.044719,0
6215595.86,,5905,30.535,30.6557,0,9.2E-6,30.829134,0.61638152,632.34051,0.9035,239.86089,0.3545,872.2014,0.9035,0.17123718,22.926318,0.029324615,99.35824,0,0,1,,,,3.8173E-5,44.17931,950.43548,20.511134,0
6215793.16,,5905,30.5244,30.6358,0,9.3E-6,30.817888,0.64053607,633.53276,0.8333,239.69973,0.3546,873.23249,0.8333,0.12862361,22.95223,0.030104048,99.341155,0,0,1,,,,3.8179E-5,45.85264,949.74221,20.557306,0
6216236.88,,5905,32.0953,32.1982,0,9.3E-6,32.395982,0.64368556,680.6948,0.7987,262.1498,0.3565,942.84461,0.7987,2.3679486,23.529263,0.022797009,99.517228,0,0,1,,,,4.0173E-5,45.90446,1049.4997,21.011704,0
6216464.72,,5905,32.0791,32.1698,0,9.3E-6,32.374199,0.66753851,682.72109,0.8317,261.87525,0.3563,944.59635,0.8317,0.23158415,23.96159,0.03277815,99.317086,0,0,1,,,,3.9563E-5,47.05853,1048.0888,21.088432,0
6217056.67,,5905,33.6278,33.7385,0,9.3E-6,33.93274,0.68091025,729.67443,1.083,284.53687,0.3836,1014.2113,1.083,0.068863601,24.758747,0.031914721,99.36121,0,0,1,,,,4.11E-5,47.92318,1151.4309,21.503552,0
6217265.95,,5905,33.6248,33.7322,0,9.2E-6,33.934804,0.70318448,730.85755,0.7944,284.58846,0.3836,1015.446,0.7944,0.42287621,24.915472,0.035207405,99.299274,0,0,1,,,,4.0905E-5,49.51749,1151.5709,21.537109,0
6217860.94,,5905,35.1791,35.2889,0,9.2E-6,35.494658,0.71201194,777.44755,1.085,307.89324,0.4176,1085.3408,1.085,0.079119194,25.671442,0.033972575,99.348638,0,0,1,,,,4.2421E-5,49.83094,1259.8708,21.903227,0
6218076.83,,5905,35.1753,35.2864,0,9.3E-6,35.49853,0.73532242,777.45895,0.8469,307.97762,0.4178,1085.4366,0.8469,0.45321241,25.859172,0.038671211,99.263996,0,0,1,,,,4.2135E-5,51.34288,1260.1456,21.901159,0
6218671.64,,5905,36.7299,36.8386,0,9.3E-6,37.057532,0.74420665,825.00546,1.225,331.96746,0.4516,1156.9729,1.225,0.070458693,26.538337,0.035658919,99.343181,0,0,1,,,,4.3743E-5,51.71834,1373.2607,22.262828,0
6218894.19,,5905,36.7267,36.8418,0,9.3E-6,37.064579,0.76831865,824.07386,0.9102,332.08321,0.4518,1156.1571,0.9102,0.52030203,26.753224,0.04069279,99.256938,0,0,1,,,,4.338E-5,53.07667,1373.783,22.233461,0
6219488.33,,5905,38.2843,38.3888,0,9.2E-6,38.621189,0.77358875,870.85123,1.282,356.73495,0.4878,1227.5862,1.282,0.060587205,27.342589,0.03946266,99.299851,0,0,1,,,,4.5056E-5,53.50645,1491.5962,22.548535,0
6219716.66,,5905,38.2767,38.3893,0,9.3E-6,38.623392,0.796684,871.70405,0.976,356.80054,0.4879,1228.5046,0.976,0.33775828,27.653552,0.041775038,99.266909,0,0,1,,,,4.459E-5,54.68518,1491.7664,22.569329,0
6220318.63,,5905,39.8353,39.9362,0,9.3E-6,40.186498,0.80683789,916.98822,1.316,382.42074,0.5238,1299.409,1.316,0.068266906,28.217849,0.039818926,99.320562,0,0,1,,,,4.6206E-5,55.3071,1614.9546,22.818316,0
6220552.55,,5905,39.8306,39.9387,0,9.2E-6,40.188948,0.82929956,917.58593,1.043,382.49356,0.5239,1300.0795,1.043,0.39748048,28.498059,0.046284688,99.217849,0,0,1,,,,4.5799E-5,56.4357,1615.1515,22.831798,0
6221159.8,,5905,41.3862,41.4851,0,9.3E-6,41.749213,0.83545999,963.77008,1.45,408.95335,0.5605,1372.7234,1.45,0.07142369,28.98172,0.041308434,99.318602,0,0,1,,,,4.7526E-5,56.99612,1742.9968,23.084748,0
6221398.48,,5905,41.3814,41.4877,0,9.3E-6,41.749252,0.85849567,965.17124,1.18,408.99218,0.5606,1374.1634,1.18,0.31729257,29.342182,0.048007626,99.217396,0,0,1,,,,4.7015E-5,57.96344,1743,23.118289,0
6222010.81,,5905,42.9416,43.033,0,9.2E-6,43.313014,0.86655742,1011.0142,1.467,436.31757,0.596,1447.3317,1.467,0.085736114,29.775967,0.042902889,99.315877,0,0,1,,,,4.8771E-5,58.68436,1876.0172,23.342042,0
6222255.59,,5905,42.9338,43.0297,0,9.3E-6,43.311836,0.8878329,1012.1712,1.178,436.32989,0.5961,1448.5011,1.178,0.34689024,30.105031,0.048369186,99.236811,0,0,1,,,,4.8296E-5,59.55193,1875.9151,23.369391,0
6222876.19,,5905,44.4907,44.5848,0,9.4E-6,44.872889,0.89500447,1057.6436,1.538,464.48184,0.6279,1522.1255,1.538,0.073212615,30.568081,0.046095195,99.288977,0,0,1,,,,4.9967E-5,60.21006,2013.5762,23.569769,0
6223125.75,,5905,44.4842,44.5847,0,9.3E-6,44.870499,0.91661837,1059.3243,1.204,464.47786,0.6279,1523.8022,1.204,0.32313051,30.954035,0.053575702,99.183403,0,0,1,,,,4.9424E-5,61.13616,2013.3617,23.608482,0
6223631,,5905,46.0574,46.1381,0,9.3E-6,46.451364,0.92420426,1101.6578,1.195,493.86783,0.6569,1595.5257,1.195,7.8670139,31.39511,0.045339028,99.324489,0,0,1,,,,5.0986E-5,61.90807,2157.7292,23.716372,0
6223886.7,,5905,46.0366,46.1348,0,9.2E-6,46.43467,0.94758084,1104.5649,1.432,493.59038,0.6566,1598.1552,1.432,0.13386073,31.647325,0.052704269,99.220082,0,0,1,,,,5.0689E-5,62.79022,2156.1786,23.787503,0
6224397.63,,5905,47.6081,47.6929,0,9.3E-6,48.014771,0.9532557,1147.7547,1.226,523.70017,0.684,1671.4548,1.226,5.4703158,32.295286,0.05115771,99.264034,0,0,1,,,,5.1937E-5,63.29465,2305.4183,23.904199,0
6224659.78,,5905,47.5917,47.6889,0,9.2E-6,47.999773,0.97889772,1151.0581,1.551,523.40901,0.6838,1674.4672,1.551,0.11858103,32.373672,0.051999954,99.252764,0,0,1,,,,5.1907E-5,64.59057,2303.9782,23.980491,0
6225183.69,,5905,49.1613,49.249,0,9.3E-6,49.576976,0.98178739,1192.8177,1.252,553.85639,0.7113,1746.6741,1.252,6.0868838,33.028275,0.055509959,99.22425,0,0,1,,,,5.3077E-5,64.74734,2457.8766,24.059912,0
6225450.44,,5905,49.1405,49.235,0,9.3E-6,49.565713,1.0087625,1195.6493,1.567,553.67304,0.7112,1749.3224,1.567,0.10707427,33.178445,0.057210245,99.203319,0,0,1,,,,5.2923E-5,66.05655,2456.7599,24.122509,0
6225962.22,,5905,50.7082,50.81,0,9.2E-6,51.140451,1.0139056,1239.3486,1.577,584.22847,0.7407,1823.577,1.577,0.24427641,34.051905,0.060646968,99.182512,0,0,1,,,,5.3757E-5,66.35689,2615.3457,24.234213,0
6226236.41,,5905,50.6998,50.7825,0,9.3E-6,51.137057,1.0438365,1240.939,1.7,584.14307,0.7406,1825.0821,1.7,0.10051606,33.832077,0.054497158,99.260211,0,0,1,,,,5.4131E-5,68.10381,2614.9986,24.266922,0
6226770.38,,5905,52.2645,52.3556,0,9.3E-6,52.703632,1.0402382,1282.6208,1.4,615.33065,0.7676,1897.9514,1.4,0.80914444,34.688656,0.062008824,99.184668,0,0,1,,,,5.492E-5,67.66415,2777.6729,24.336478,0
6227048.5,,5905,52.2451,52.3362,0,9.3E-6,52.696347,1.0712651,1284.9227,1.693,615.2123,0.7675,1900.135,1.693,0.10424773,34.622594,0.062196095,99.180067,0,0,1,,,,5.5089E-5,69.37731,2776.905,24.383524,0
6227566.27,,5905,53.8161,53.9132,0,9.3E-6,54.260224,1.0738246,1326.9159,2.05,647.9602,0.7866,1974.8761,2.05,0.102084,35.714316,0.070817189,99.10129,0,0,1,,,,5.5523E-5,69.24519,2944.1719,24.454671,0
6227851.66,,5905,53.8017,53.8838,0,9.3E-6,54.264195,1.1042404,1328.3304,1.755,648.00788,0.7866,1976.3383,1.755,0.12758845,35.300645,0.060126127,99.227669,0,0,1,,,,5.6183E-5,71.42863,2944.6029,24.478949,0
6228375.78,,5905,55.3648,55.4705,0,9.3E-6,55.818818,1.101327,1372.0183,2.163,682.41981,0.7963,2054.4381,2.163,0.08663495,36.586812,0.077967964,99.040308,0,0,1,,,,5.6396E-5,70.60129,3115.7404,24.579853,0
6228667.75,,5905,55.3529,55.4366,0,9.3E-6,55.830239,1.1366364,1372.9474,1.731,682.59767,0.7963,2055.5451,1.731,0.11431283,36.033195,0.062310146,99.221001,0,0,1,,,,5.7246E-5,73.17362,3117.0156,24.591465,0
6229194.23,,5905,56.9097,57.0182,0,9.4E-6,57.381823,1.1311907,1414.6629,2.398,718.41524,0.799,2133.0782,2.398,0.079642508,37.347899,0.082294437,99.014649,0,0,1,,,,5.7364E-5,72.06639,3292.6736,24.653503,0
6229491.42,,5905,56.9023,56.9854,0,9.3E-6,57.39488,1.1681081,1416,1.741,718.67464,0.799,2134.6746,1.741,0.11750122,36.747591,0.065013194,99.208523,0,0,1,,,,5.8294E-5,74.6958,3294.1723,24.67119,0
6230020.83,,5905,58.4646,58.574,0,9.3E-6,58.939657,1.1589174,1457.7268,2.54,755.79864,0.7947,2213.5254,2.54,0.07865005,38.116754,0.087006086,98.986197,0,0,1,,,,5.8331E-5,73.49518,3473.8832,24.732529,0
6230323.36,,5905,58.4559,58.5372,0,9.3E-6,58.957383,1.1974949,1459.0356,1.843,756.14214,0.7946,2215.1777,1.843,0.11941919,37.479608,0.068111265,99.192545,0,0,1,,,,5.9313E-5,76.23351,3475.973,24.747292,0
6230797.05,,5905,60.0054,60.1398,0,9.2E-6,60.485369,1.1908948,1502.752,2.699,794.39894,0.7834,2297.1509,2.699,0.11407335,39.244632,0.10321601,98.839312,0,0,1,,,,5.8829E-5,74.95922,3658.4799,24.844884,0
6231108.56,,5905,60.0133,60.1027,0,9.3E-6,60.527565,1.2352936,1500.2715,1.641,795.30217,0.7831,2295.5736,1.641,0.21426079,38.17615,0.072214299,99.165561,0,0,1,,,,6.0348E-5,78.48926,3663.5861,24.786582,0