File: heat capacity project/HC_AJ2145_Co-imidazole.dat
[Header]
TITLE,HC_AJ2145_Co-imidazole.dat
BYAPP,HeatCapacity,3.8.2,1.7
INFO,3.11,MASS:Sample Mass (mg)
INFO,0,MASSERR:Sample Mass Error (mg)
INFO,311.25,MOLWGHT:Formula Weight (g/mole)
INFO,0,ATOMS:Atoms per Formula Unit
INFO,PPMS Heat Capacity Option 3.8.2 Build 2,APPNAME
DATATYPE,TIME,1
DATATYPE,COMMENT,2
STARTUPAXIS, X, 8, LINEAR, AUTO
STARTUPAXIS, Y1, 10, LINEAR, AUTO
[Data]
Time Stamp (Seconds),Comment (),System Status (Code),Puck Temp (Kelvin),System Temp (Kelvin),Field (Oersted),Pressure (Torr),Sample Temp (Kelvin),Temp Rise (Kelvin),Samp HC (µJ/K),Samp HC Err (µJ/K),Addenda HC (µJ/K),Addenda HC Err (µJ/K),Total HC (µJ/K),Total HC Err (µJ/K),Fit Deviation (ChiSquare),Time Const tau1 (seconds),Time Const tau2 (seconds),Sample Coupling (Percent),Debye Temp (Kelvin),Debye Temp Err (Kelvin),Cal Correction (Factor),Therm Resist (Ohms),Htr Resist (Ohms),Puck Resist (Ohms),Wire Cond (W/K),Meas Time (seconds),Temp Squared (K^2),Samp HC/Temp (µJ/K/K),Addenda Offset HC (µJ/K)
3847596.03,CALFILE: Puck1070shorten2.cal - Addenda #82 measured on 2/10/2019 from 2.1734371 to 40.28299 K
3847596.16,,5905,39.9956,40.188,-0.056,9.3E-6,40.276801,0.79678683,553.76731,1.099,421.50144,0.8718,975.26875,1.099,0.4218551,21.334453,0.23352675,95.606787,0,0,1,,,,4.6398E-5,39.55859,1622.2207,13.749039,0
3848386.73,,5905,32.708,32.9209,-0.056,9.3E-6,33.004183,0.74006351,413.73941,0.9727,298.05613,0.8074,711.79554,0.9727,0.46165334,17.907455,0.19009558,95.69711,0,0,1,,,,4.0359E-5,42.73134,1089.2761,12.535969,0
3849035.42,,5905,26.712,26.9268,-0.056,9.3E-6,26.940052,0.62141176,309.47083,0.8914,208.43823,0.4624,517.90906,0.8914,25.278131,16.628249,0.20404614,94.96672,0,0,1,,,,3.1743E-5,36.15485,725.76641,11.487388,0
3849572.38,,5905,21.8804,22.0045,-0.056,9.2E-6,22.06246,0.49701997,214.77609,0.4261,144.23388,0.2781,359.00997,0.4261,0.22738925,12.565176,0.122401,95.991133,0,0,1,,,,2.9003E-5,30.69257,486.75216,9.7349109,0
3850034.73,,5905,17.887,17.9985,-0.056,9.2E-6,18.029735,0.39887887,151.90697,0.4147,96.907556,0.2177,248.81453,0.4147,0.30723272,10.705128,0.10991905,95.726206,0,0,1,,,,2.3633E-5,24.9018,325.07136,8.4253578,0
3850460.05,,5905,14.6316,14.7723,-0.056,9.3E-6,14.785867,0.32389394,108.21986,0.2391,64.020792,0.144,172.24065,0.2391,1.0405181,9.0459798,0.082300527,96.133884,0,0,1,,,,1.9346E-5,21.12126,218.62185,7.3191424,0
3850891.55,,5905,11.9725,12.1034,-0.056,9.3E-6,12.117061,0.26092481,77.715744,0.1394,41.40269,0.08322,119.11843,0.1394,0.94669426,7.8280127,0.062941384,96.471158,0,0,1,,,,1.5456E-5,17.94035,146.82316,6.4137455,0
3851357.5,,5905,9.79411,9.9037,-0.056,9.2E-6,9.9121558,0.20724581,59.138331,0.09655,26.028149,0.05155,85.16648,0.09655,0.600513,7.2068637,0.049432296,96.770059,0,0,1,,,,1.2009E-5,15.56653,98.250832,5.9662431,0
3851801.78,,5905,8.0125,8.1103,-0.056,9.2E-6,8.1106058,0.16218499,49.965952,0.1022,16.056728,0.04646,66.02268,0.1022,0.250359,7.150348,0.037294299,97.153179,0,0,1,,,,9.3893E-6,14.16278,65.781926,6.1605696,0
3852528.64,,5905,6.55034,6.6656,-0.056,9.3E-6,6.6493842,0.12688118,46.107295,0.07035,9.4774353,0.03702,55.584731,0.07035,0.72122592,7.8535995,0.028327804,97.423806,0,0,1,,,,7.2069E-6,14.30046,44.21431,6.93407,0
3853040.44,,5905,5.3555,5.4596,-0.056,9.3E-6,5.4452723,0.12856207,68.539451,0.8412,5.5863397,0.0144,74.125791,0.8412,99.110403,15.111284,0.035150784,96.577308,0,0,1,,,,5.0543E-6,32.41104,29.650991,12.586965,0
3853625.38,,5905,4.38144,4.4646,-0.056,9.4E-6,4.4574583,0.091304896,40.2487,0.144,3.1276386,0.007924,43.376339,0.144,6.3892131,10.043338,0.012042327,98.183855,0,0,1,,,,4.3878E-6,19.99759,19.868934,9.0295182,0
3854051.83,,5905,3.57852,3.6428,-0.056,9.2E-6,3.6380159,0.074628109,12.476744,0.05309,1.703009,0.004305,14.179753,0.05309,0.97260951,4.2592673,0.0099741713,97.7559,0,0,1,,,,3.3885E-6,8.264908,13.23516,3.4295463,0
3854340.67,,5905,2.92433,2.9678,-0.056,9.2E-6,2.9715966,0.060945017,3.7382544,0.01755,0.9237842,0.002237,4.6620386,0.01755,0.23310088,1.7860899,0.0071173753,97.472853,0,0,1,,,,2.6539E-6,3.474464,8.8303861,1.2579953,0
3854577.08,,5905,2.39453,2.4172,-0.056,9.3E-6,2.4293855,0.050100064,1.2434426,0.00381,0.50533684,0.001035,1.7487795,0.00381,3.3619522,0.82718146,0.0053015998,96.878068,0,0,1,,,,2.1488E-6,1.643098,5.9019139,0.51183423,0
3856058.48,,5905,2.00698,2.015,-0.056,9.3E-6,2.0300841,0.04355947,0.58487465,0.001546,0.30682389,0.0008294,0.89169855,0.001546,16.74536,0.51617441,0.0040288349,96.556667,0,0,1,,,,1.7542E-6,1.037347,4.1212416,0.28810365,0
3856341.48,,5905,2.13128,2.1417,-0.056,9.2E-6,2.1548463,0.042461702,0.73053322,0.002457,0.3597991,0.0008022,1.0903323,0.002457,1.8729497,0.59955397,0.0050958419,96.168497,0,0,1,,,,1.8514E-6,1.045674,4.6433624,0.33901872,0
3856535.17,,5905,2.26244,2.279,-0.056,9.3E-6,2.2886188,0.042938395,0.93939902,0.00287,0.42570947,0.0008655,1.3651085,0.00287,3.4547974,0.68804939,0.0052936239,96.419619,0,0,1,,,,2.0192E-6,1.16153,5.2377758,0.41046549,0
3856731.59,,5905,2.39419,2.4171,-0.056,9.3E-6,2.4230806,0.044690444,1.2430767,0.004551,0.5018792,0.001026,1.7449559,0.004551,3.3988345,0.86477256,0.006366896,96.402476,0,0,1,,,,2.0563E-6,1.34105,5.8713198,0.51301498,0
3856923.78,,5905,2.52578,2.5552,-0.056,9.2E-6,2.5594524,0.048678777,1.5885019,0.00538,0.58829219,0.001297,2.1767941,0.00538,2.5201174,0.97300125,0.0054681441,97.143944,0,0,1,,,,2.2724E-6,1.697022,6.5507966,0.62064132,0
3857130.11,,5905,2.65801,2.6945,-0.056,9.4E-6,2.6955146,0.051288858,2.1080831,0.009656,0.68390436,0.001698,2.7919875,0.009656,0.11178504,1.1897612,0.0054824159,97.498934,0,0,1,,,,2.3812E-6,2.052929,7.2657988,0.78207077,0
3857326.2,,5905,2.78942,2.8312,-0.056,9.2E-6,2.8288032,0.051192425,2.7614875,0.01013,0.79171355,0.002026,3.5532011,0.01013,0.71804721,1.3952673,0.0062204786,97.410602,0,0,1,,,,2.5877E-6,2.360073,8.0021273,0.97620348,0
3857525.41,,5905,2.92098,2.9668,-0.056,9.3E-6,2.9629352,0.053898914,3.6641325,0.01755,0.91437126,0.002224,4.5785038,0.01755,0.40326131,1.7351862,0.0064473492,97.659093,0,0,1,,,,2.6793E-6,2.794931,8.7789848,1.2366563,0
3857717.2,,5905,3.05408,3.1058,-0.056,9.2E-6,3.0974306,0.056793708,4.6190108,0.02171,1.0508629,0.002461,5.6698738,0.02171,1.040427,2.034642,0.0080975388,97.339994,0,0,1,,,,2.8374E-6,3.440541,9.5940763,1.4912395,0
3857915.98,,5905,3.18601,3.2422,-0.056,9.3E-6,3.2321985,0.060143099,5.9748895,0.02035,1.1948456,0.002832,7.169735,0.02035,0.29975136,2.4684334,0.005990142,98.240317,0,0,1,,,,2.9408E-6,4.126704,10.447107,1.8485528,0
3858129.81,,5905,3.31877,3.378,-0.056,9.2E-6,3.3670181,0.06011461,7.9120451,0.03806,1.3498422,0.003277,9.2618873,0.03806,2.2024507,2.925143,0.0081369859,97.741669,0,0,1,,,,3.2198E-6,4.887586,11.336811,2.3498671,0
3858349.64,,5905,3.45207,3.5141,-0.056,9.2E-6,3.502269,0.064952123,9.8954661,0.0285,1.5196798,0.003759,11.415146,0.0285,0.38893481,3.541702,0.0068680739,98.304971,0,0,1,,,,3.2649E-6,5.976524,12.265888,2.8254443,0
3858576.08,,5905,3.58668,3.6532,-0.056,9.3E-6,3.6370233,0.068201125,12.461443,0.03395,1.7017823,0.004301,14.163225,0.03395,0.73540702,4.2333074,0.0081196574,98.16699,0,0,1,,,,3.3941E-6,7.241656,13.227938,3.4262753,0
3858803.77,,5905,3.71663,3.7879,-0.056,9.2E-6,3.7713525,0.071404574,15.388264,0.07101,1.8969616,0.004843,17.285226,0.07101,1.2927128,4.9187176,0.008617867,98.187222,0,0,1,,,,3.5657E-6,8.66819,14.223099,4.080304,0
3859052.14,,5905,3.85181,3.9276,-0.056,9.3E-6,3.9085561,0.073776001,18.896648,0.08696,2.1109761,0.005292,21.007624,0.08696,1.5213103,5.8007114,0.01079269,97.914303,0,0,1,,,,3.6841E-6,9.98217,15.276811,4.8346876,0
3859323.84,,5905,3.98544,4.0639,-0.056,9.3E-6,4.0451452,0.07666403,23.315661,0.09459,2.3408366,0.005573,25.656498,0.09459,1.0716307,6.9442239,0.013247362,97.663091,0,0,1,,,,3.7678E-6,11.81706,16.3632,5.7638625,0
3859697.73,,5905,4.08686,4.1641,-0.056,9.4E-6,4.1506954,0.079787546,26.987169,0.07414,2.526643,0.00583,29.513812,0.07414,2.7452876,7.4348733,0.009204232,98.401183,0,0,1,,,,4.0236E-6,13.18035,17.228272,6.5018428,0
3859992.39,,5905,4.18618,4.2658,-0.056,9.3E-6,4.2512802,0.081418936,31.139712,0.1192,2.7147777,0.006246,33.85449,0.1192,0.17394098,8.3618356,0.010387701,98.295482,0,0,1,,,,4.1082E-6,15.14509,18.073383,7.3247848,0
3860304.33,,5905,4.28786,4.369,-0.056,9.3E-6,4.3535531,0.084789637,35.337366,0.1231,2.9152049,0.00695,38.252571,0.1231,0.72267363,9.3856923,0.012727186,98.046649,0,0,1,,,,4.145E-6,16.93237,18.953424,8.1169026,0
3860655.25,,5905,4.38991,4.4738,-0.056,9.3E-6,4.456996,0.086269869,40.401479,0.1608,3.1272028,0.007922,43.528681,0.1608,0.33955561,10.343603,0.013842392,97.96276,0,0,1,,,,4.2838E-6,18.64303,19.864813,9.064733,0
3861033.13,,5905,4.49003,4.574,-0.056,9.3E-6,4.5597288,0.087852827,45.490587,0.1847,3.3473783,0.009011,48.837966,0.1847,0.32618115,11.143419,0.01277369,98.179945,0,0,1,,,,4.4532E-6,20.38229,20.791127,9.9765994,0
3861440.41,,5905,4.59171,4.6786,-0.056,9.3E-6,4.6621224,0.089384512,51.814911,0.2074,3.5748578,0.01008,55.389768,0.2074,0.44978744,12.357663,0.015035159,97.953109,0,0,1,,,,4.5643E-6,22.40188,21.735385,11.114018,0
3861868.16,,5905,4.69047,4.7782,-0.056,9.3E-6,4.7634193,0.09086298,58.032294,0.212,3.8066461,0.01097,61.83894,0.212,0.9670688,13.427731,0.015102349,98.02307,0,0,1,,,,4.6872E-6,24.14394,22.690163,12.182907,0
3862320.52,,5905,4.79341,4.8855,-0.056,9.3E-6,4.8655895,0.093621324,64.8865,0.1958,4.0475351,0.01172,68.934035,0.1958,1.3283404,14.729754,0.018253522,97.717232,0,0,1,,,,4.7769E-6,26.6228,23.673961,13.335794,0
3862773.67,,5905,4.89128,4.9863,-0.056,9.3E-6,4.9663199,0.095617919,72.048742,0.2431,4.2907376,0.01238,76.339479,0.2431,0.29517222,15.804687,0.016523057,97.997635,0,0,1,,,,4.9182E-6,28.77778,24.664334,14.507471,0
3863251.28,,5905,4.99314,5.0887,-0.056,9.4E-6,5.0679553,0.097357157,79.927211,0.2918,4.5445158,0.01298,84.471727,0.2918,0.28962676,17.069157,0.016501646,98.071264,0,0,1,,,,5.036E-6,30.90712,25.68417,15.771096,0
3863768.5,,5905,5.09458,5.1964,-0.056,9.3E-6,5.170508,0.099848015,88.03351,0.2658,4.8092971,0.01353,92.842807,0.2658,0.33218593,18.122451,0.016426432,98.1264,0,0,1,,,,5.2111E-6,33.63476,26.734153,17.026085,0
3864333.06,,5905,5.19544,5.296,-0.056,9.3E-6,5.273069,0.10301817,94.68321,0.2446,5.0865689,0.01404,99.769779,0.2446,0.39926062,19.191311,0.019839633,97.82521,0,0,1,,,,5.3029E-6,35.95089,27.805257,17.955997,0
3864889.17,,5905,5.29373,5.3992,-0.056,9.3E-6,5.3779135,0.11497912,88.10429,0.5347,5.3835755,0.01439,93.487866,0.5347,2.3845813,18.171876,0.024258804,97.490808,0,0,1,,,,5.2624E-6,37.64845,28.921953,16.382616,0
3865463.67,,5905,5.39326,5.4978,-0.056,9.3E-6,5.4853123,0.14595662,58.094645,0.749,5.7045477,0.01437,63.799192,0.749,29.259691,13.601451,0.054035788,94.947467,0,0,1,,,,4.8984E-6,35.80723,30.088651,10.590946,0
3865927.86,,5905,5.49112,5.5974,-0.056,9.4E-6,5.5851566,0.1343609,47.043345,0.1991,6.0076709,0.01427,53.051016,0.1991,1.6226192,9.7821759,0.025779442,97.3341,0,0,1,,,,5.5403E-6,25.72239,31.193974,8.4229232,0
3866290.48,,5905,5.58332,5.693,-0.056,9.3E-6,5.6724016,0.1199514,45.275969,0.1101,6.2887016,0.01431,51.56467,0.1101,0.1254242,9.0660001,0.020779947,97.833644,0,0,1,,,,5.785E-6,19.23325,32.17614,7.9817989,0
3866620.98,,5905,5.68426,5.7966,-0.056,9.3E-6,5.7716993,0.11916848,44.779746,0.152,6.6061863,0.01472,51.385932,0.152,0.3699024,8.9210752,0.025132782,97.450829,0,0,1,,,,5.8748E-6,18.01316,33.312513,7.7585029,0
3866949.84,,5905,5.78425,5.8942,-0.056,9.3E-6,5.8716826,0.11960154,45.115875,0.1029,6.9230433,0.01574,52.038918,0.1029,0.097209409,8.8166477,0.024921868,97.51744,0,0,1,,,,6.0156E-6,17.44661,34.476657,7.6836365,0
3867266.55,,5905,5.88428,5.9915,-0.056,9.2E-6,5.9752459,0.12311594,44.942078,0.07034,7.2453985,0.01783,52.187477,0.07034,0.29135912,8.4901519,0.02103993,97.905601,0,0,1,,,,6.2446E-6,17.55465,35.703563,7.5213772,0
3867609.06,,5905,5.98328,6.0928,-0.056,9.3E-6,6.0717688,0.12326072,44.969429,0.1392,7.5440432,0.02099,52.513472,0.1392,0.12507604,8.6632856,0.029138334,97.229075,0,0,1,,,,6.1887E-6,16.64694,36.866376,7.4063144,0
3867922.95,,5905,6.08249,6.1928,-0.056,9.3E-6,6.1736632,0.12603702,44.980891,0.1126,7.852998,0.02497,52.833889,0.1126,1.623188,8.3007899,0.022844839,97.802898,0,0,1,,,,6.4689E-6,16.70721,38.114117,7.2859321,0
3868200.13,,5905,6.18073,6.291,-0.056,9.3E-6,6.2712447,0.12783262,45.556527,0.063,8.1552581,0.02897,53.711785,0.063,0.15184748,8.2356226,0.021927047,97.912973,0,0,1,,,,6.6222E-6,16.57545,39.328511,7.2643517,0
3868499.84,,5905,6.28175,6.3901,-0.056,9.3E-6,6.3749916,0.13057531,45.566792,0.08646,8.4887292,0.03286,54.055521,0.08646,0.25796249,8.1314053,0.024821224,97.670555,0,0,1,,,,6.7608E-6,16.54388,40.640518,7.1477414,0
3868808.58,,5905,6.38208,6.4929,-0.056,9.2E-6,6.4762479,0.13279724,45.923625,0.1256,8.8328963,0.03574,54.756521,0.1256,0.20989177,8.1706921,0.029652378,97.286539,0,0,1,,,,6.8335E-6,16.41823,41.941787,7.091085,0
3869093.92,,5905,6.48236,6.5971,-0.056,9.4E-6,6.5760334,0.1329174,45.843329,0.1398,9.1966658,0.03713,55.039995,0.1398,0.16355001,8.0198965,0.032001378,97.098945,0,0,1,,,,7.0058E-6,15.8355,43.244215,6.9712738,0
3869458.48,,5905,6.57971,6.6963,-0.056,9.3E-6,6.6719703,0.12947749,46.393924,0.09364,9.5675461,0.03681,55.96147,0.09364,0.050829873,7.9018523,0.025710569,97.683622,0,0,1,,,,7.1979E-6,14.23712,44.515187,6.9535568,0
3869761.38,,5905,6.88196,7.0083,-0.056,9.3E-6,6.9795152,0.14278707,46.665416,0.1307,10.864136,0.0296,57.529552,0.1307,0.29246168,7.7240284,0.031090493,97.349089,0,0,1,,,,7.5821E-6,15.66731,48.713632,6.6860541,0
3870052.61,,5905,7.18262,7.3117,-0.056,9.3E-6,7.282572,0.14885843,47.408721,0.0808,12.211631,0.02464,59.620352,0.0808,0.19809229,7.5642373,0.0289869,97.631587,0,0,1,,,,8.0032E-6,15.2784,53.035855,6.509887,0
3870330.55,,5905,7.4851,7.6173,-0.056,9.3E-6,7.5873221,0.15506763,48.319669,0.08901,13.58951,0.03111,61.90918,0.08901,0.19867473,7.4877721,0.033476769,97.374371,0,0,1,,,,8.4045E-6,15.03635,57.567457,6.3684747,0
3870608.78,,5905,7.79056,7.92,-0.056,9.3E-6,7.8948758,0.16376825,49.035045,0.1032,15.023704,0.04187,64.058749,0.1032,0.11091091,7.3857435,0.03702435,97.192942,0,0,1,,,,8.8208E-6,15.02303,62.329064,6.2109964,0
3870903.27,,5905,8.09404,8.2263,-0.056,9.3E-6,8.2021057,0.16852354,49.737886,0.08725,16.506939,0.04689,66.244825,0.08725,0.26818334,7.2118682,0.032491796,97.583712,0,0,1,,,,9.3143E-6,14.49602,67.274538,6.0640387,0
3871177.3,,5905,8.39373,8.53,-0.056,9.2E-6,8.5008261,0.17086245,51.813339,0.1741,17.997223,0.0441,69.810562,0.1741,1.5179741,7.3507495,0.047229849,96.628451,0,0,1,,,,9.6808E-6,14.23149,72.264044,6.0950946,0
3871470.86,,5905,8.70105,8.8443,-0.056,9.3E-6,8.8106448,0.17939704,52.388847,0.117,19.602425,0.03922,71.991272,0.117,1.0361182,7.1994675,0.044281855,96.888659,0,0,1,,,,1.0171E-5,14.34294,77.627461,5.9460855,0
3871744.42,,5905,9.0017,9.1447,-0.056,9.3E-6,9.1163715,0.18346127,55.162516,0.1585,21.275037,0.03841,76.437553,0.1585,0.08825127,7.2039467,0.043483441,96.989828,0,0,1,,,,1.0783E-5,14.4015,83.10823,6.050929,0
3872019.81,,5905,9.30318,9.4438,-0.056,9.4E-6,9.4196807,0.18890094,56.368516,0.1596,23.039307,0.04209,79.407823,0.1596,0.57280955,7.3730166,0.058072198,96.171932,0,0,1,,,,1.0988E-5,14.15195,88.730385,5.9841218,0
3872294.19,,5905,9.60928,9.7523,-0.056,9.3E-6,9.7263429,0.19517881,58.292594,0.1748,24.877982,0.04782,83.170576,0.1748,0.061714131,7.2589747,0.050520846,96.680478,0,0,1,,,,1.1652E-5,14.42719,94.601745,5.9932695,0
3872576.58,,5905,9.91358,10.0569,-0.056,9.3E-6,10.032405,0.19977067,60.134107,0.1572,26.794293,0.05385,86.9284,0.1572,0.13834657,7.3454079,0.055485442,96.460772,0,0,1,,,,1.2044E-5,14.26675,100.64916,5.9939869,0
3873045.64,,5905,10.2444,10.3285,-0.056,9.2E-6,10.330413,0.20697852,61.781744,0.1001,28.728071,0.06011,90.509815,0.1001,0.57589615,7.231854,0.05071409,96.768947,0,0,1,,,,1.2712E-5,14.42419,106.71743,5.9805687,0
3873325.13,,5905,10.5335,10.6114,-0.056,9.3E-6,10.60937,0.21009362,63.961656,0.1239,30.606827,0.0667,94.568483,0.1239,0.58801475,7.3949002,0.056266344,96.532545,0,0,1,,,,1.3E-5,14.38151,112.55874,6.0287891,0
3873606.77,,5905,10.8365,10.9169,-0.056,9.3E-6,10.91506,0.21659649,66.406954,0.1314,32.719745,0.07354,99.126699,0.1314,0.59060129,7.4442489,0.057329687,96.527935,0,0,1,,,,1.3533E-5,14.67378,119.13853,6.0839752,0
3873887.22,,5905,11.1411,11.2217,-0.056,9.3E-6,11.222499,0.22307103,69.14518,0.142,34.8875,0.07879,104.03268,0.142,0.68537671,7.5595267,0.060501348,96.422394,0,0,1,,,,1.3989E-5,14.83904,125.94449,6.1612995,0
3874170.19,,5905,11.4428,11.5249,-0.056,9.3E-6,11.527923,0.22955485,71.826835,0.142,37.0729,0.08124,108.89973,0.142,0.8003956,7.6492742,0.06128976,96.446236,0,0,1,,,,1.4467E-5,15.04731,132.893,6.2306833,0
3874455.7,,5905,11.7474,11.8294,-0.056,9.2E-6,11.835376,0.2346731,74.858062,0.1474,39.305482,0.08212,114.16354,0.1474,1.1360797,7.7783869,0.064043607,96.369536,0,0,1,,,,1.4917E-5,15.20442,140.07613,6.3249415,0
3874742.55,,5905,12.0518,12.1338,-0.056,9.3E-6,12.142377,0.24061779,77.888242,0.1558,41.60466,0.08339,119.4929,0.1558,0.61591413,7.8594508,0.065686609,96.335747,0,0,1,,,,1.5452E-5,15.45889,147.43732,6.4145793,0
3875028.91,,5905,12.3546,12.438,-0.056,9.3E-6,12.445784,0.24688753,81.019702,0.1635,43.949807,0.08698,124.96951,0.1635,1.0621753,7.9789086,0.067297121,96.320521,0,0,1,,,,1.5916E-5,15.69505,154.89753,6.5098113,0
3875318.08,,5905,12.6586,12.7443,-0.056,9.2E-6,12.749783,0.25340282,84.174563,0.169,46.379195,0.09374,130.55376,0.169,0.94232734,8.1396018,0.070410848,96.245201,0,0,1,,,,1.6302E-5,15.91133,162.55698,6.6020386,0
3875608.72,,5905,12.9615,13.0502,-0.056,9.4E-6,13.054279,0.25971099,87.427514,0.1875,48.882342,0.1025,136.30986,0.1875,0.9421402,8.2940514,0.073302506,96.181473,0,0,1,,,,1.6706E-5,16.12803,170.41419,6.6972306,0
3875900.11,,5905,13.2647,13.3535,-0.056,9.2E-6,13.358072,0.26501619,91.013073,0.1976,51.423395,0.112,142.43647,0.1976,1.0674894,8.4313559,0.075238539,96.156843,0,0,1,,,,1.7172E-5,16.43969,178.43809,6.813339,0
3876192.84,,5905,13.5692,13.6601,-0.056,9.3E-6,13.663728,0.27263099,94.409815,0.2024,54.045986,0.1212,148.4558,0.2024,1.0734271,8.5397769,0.076477155,96.158201,0,0,1,,,,1.7668E-5,16.72627,186.69746,6.909521,0
3876487.91,,5905,13.8724,13.9634,-0.056,9.3E-6,13.968584,0.27832716,98.173231,0.2206,56.703196,0.1286,154.87643,0.2206,1.1339911,8.7000374,0.079505146,96.09033,0,0,1,,,,1.8096E-5,16.97235,195.12133,7.028145,0
3876783.55,,5905,14.1758,14.2671,-0.056,9.4E-6,14.27342,0.2839724,101.93935,0.223,59.4045,0.1348,161.34385,0.223,1.0411046,8.8444538,0.082224282,96.033257,0,0,1,,,,1.8546E-5,17.24976,203.73053,7.1419006,0
3877081.02,,5905,14.48,14.5707,-0.056,9.2E-6,14.578486,0.29020207,105.3255,0.2304,62.140075,0.1404,167.46557,0.2304,1.1070893,8.9548567,0.082422875,96.086105,0,0,1,,,,1.9005E-5,17.55667,212.53225,7.2247214,0
3877381.39,,5905,14.7835,14.876,-0.056,9.2E-6,14.884611,0.2961426,109.06233,0.2495,64.955165,0.1459,174.0175,0.2495,0.87073737,9.0913909,0.085095285,96.030784,0,0,1,,,,1.9455E-5,17.83161,221.55164,7.3271875,0
3877774.98,,5905,14.9824,15.0967,-0.056,9.3E-6,15.095811,0.2950725,111.96034,0.2428,66.941323,0.1499,178.90166,0.2428,3.7060803,9.1703559,0.085641982,96.043846,0,0,1,,,,1.9826E-5,17.03059,227.88351,7.4166496,0
3878095.14,,5905,16.0267,16.1247,-0.056,9.3E-6,16.134755,0.3158465,124.70923,0.3019,77.056946,0.1753,201.76618,0.3019,0.47524873,9.6375398,0.092567703,95.967525,0,0,1,,,,2.1275E-5,18.43056,260.33031,7.72923,0
3878418.86,,5905,17.0726,17.161,-0.056,9.3E-6,17.177623,0.33606387,138.97034,0.3313,87.836859,0.202,226.8072,0.3313,0.67077835,10.144114,0.099447697,95.908417,0,0,1,,,,2.272E-5,19.24554,295.07072,8.0901964,0
3878749.91,,5905,18.107,18.2221,-0.056,9.2E-6,18.227263,0.35536676,154.74716,0.4066,99.109298,0.2209,253.85646,0.4066,0.32574838,10.720659,0.10894425,95.773876,0,0,1,,,,2.4072E-5,20.0934,332.23311,8.489874,0
3879085.03,,5905,19.1511,19.2469,-0.056,9.3E-6,19.260255,0.37625576,170.31203,0.3882,110.66643,0.236,280.97846,0.3882,3.6561913,11.265084,0.11596923,95.73408,0,0,1,,,,2.5355E-5,21.18273,370.95743,8.8426675,0
3879447.09,,5905,20.1818,20.3267,-0.056,9.3E-6,20.323593,0.39895926,187.44404,0.4719,123.06046,0.2469,310.5045,0.4719,0.23564405,11.947381,0.13023249,95.496555,0,0,1,,,,2.6441E-5,22.31541,413.04843,9.2229774,0
3879797.52,,5905,21.2357,21.3321,-0.056,9.3E-6,21.354291,0.41947192,202.2821,0.3911,135.47858,0.2626,337.76069,0.3911,1.061257,12.158535,0.12641908,95.721498,0,0,1,,,,2.823E-5,23.38591,456.00575,9.4726677,0
3880178.59,,5905,22.2661,22.4236,-0.056,9.3E-6,22.423272,0.4430009,221.106,0.5302,148.89169,0.2874,369.99769,0.5302,0.27316469,13.029754,0.14295832,95.493365,0,0,1,,,,2.888E-5,24.4629,502.80312,9.8605592,0
3880537.66,,5905,23.3145,23.435,-0.056,9.4E-6,23.452776,0.46297548,238.22413,0.532,162.06908,0.32,400.29321,0.532,0.32659455,13.41074,0.14612066,95.534097,0,0,1,,,,3.0348E-5,25.44915,550.03268,10.157609,0
3880920.14,,5905,24.3525,24.4943,-0.056,9.3E-6,24.509338,0.48703032,256.34937,0.6027,175.6437,0.3722,431.99307,0.6027,0.2896632,14.008745,0.15566476,95.453441,0,0,1,,,,3.1361E-5,26.60431,600.70766,10.459253,0
3881294.61,,5905,25.3922,25.5429,-0.056,9.3E-6,25.559063,0.50875087,275.35062,0.671,189.35423,0.4312,464.70485,0.671,0.25565038,14.52118,0.15976462,95.501282,0,0,1,,,,3.2537E-5,27.56316,653.26571,10.773111,0
3881709.64,,5905,26.4369,26.5964,-0.056,9.4E-6,26.617231,0.53121951,293.97516,0.7296,203.82792,0.4627,497.80307,0.7296,0.18936548,15.036192,0.16685825,95.470656,0,0,1,,,,3.3661E-5,28.65954,708.47699,11.044543,0
3882129.5,,5905,27.478,27.6593,-0.056,9.2E-6,27.674124,0.55335818,312.19305,0.7846,219.03657,0.4535,531.22962,0.7846,0.14413209,15.586345,0.17426857,95.447837,0,0,1,,,,3.4651E-5,29.56768,765.85713,11.281046,0
3882571.67,,5905,28.5264,28.7094,-0.056,9.3E-6,28.730826,0.57224154,331.6574,0.7807,234.55898,0.4529,566.21637,0.7807,0.2474126,16.081589,0.1832708,95.368596,0,0,1,,,,3.5803E-5,30.34455,825.46038,11.543608,0
3883027.69,,5905,29.5734,29.7502,-0.056,9.3E-6,29.781411,0.59005678,351.33134,0.7666,249.86823,0.5168,601.19957,0.7666,0.3388065,16.51059,0.18630801,95.418575,0,0,1,,,,3.7017E-5,31.18619,886.93244,11.797001,0
3883530.8,,5905,30.6243,30.7893,-0.056,9.4E-6,30.835674,0.61270487,370.61389,0.806,265.15262,0.6458,635.7665,0.806,1.3335507,16.804798,0.18596743,95.510966,0,0,1,,,,3.8444E-5,32.3867,950.83879,12.018997,0
3884026.13,,5905,31.6751,31.8316,-0.056,9.4E-6,31.890432,0.63203116,391.37918,0.9276,280.7901,0.7669,672.16928,0.9276,0.56966887,17.156809,0.1823934,95.687593,0,0,1,,,,3.9783E-5,33.37336,1016.9996,12.272621,0
3884726.58,,5905,32.7175,32.8325,-0.056,9.3E-6,32.905602,0.6542921,413.07738,0.9666,296.5877,0.8082,709.66508,0.9666,0.38098101,17.778135,0.19534942,95.545248,0,0,1,,,,4.0556E-5,34.37766,1082.7786,12.553406,0
3885241.92,,5905,33.7625,33.9052,-0.056,9.4E-6,33.981532,0.6747805,432.35094,0.9015,314.08253,0.7685,746.43348,0.9015,2.5051216,18.124911,0.19721252,95.59777,0,0,1,,,,4.1826E-5,35.62096,1154.7445,12.723115,0
3885925.98,,5905,34.8015,34.9258,-0.056,9.4E-6,35.003107,0.69674318,450.32618,0.9227,331.16392,0.7047,781.4901,0.9227,0.28214883,18.685147,0.20855663,95.495569,0,0,1,,,,4.2487E-5,36.29171,1225.2175,12.86532,0
3887209.83,,5905,35.9868,36.1452,-0.056,9.3E-6,36.201929,0.70476532,473.79253,0.8777,351.48116,0.6695,825.27368,0.8777,16.021836,19.618543,0.23262413,95.22628,0,0,1,,,,4.277E-5,34.88915,1310.5797,13.087494,0
3887900.13,,5905,37.0083,37.131,-0.056,9.3E-6,37.228346,0.74537074,492.37131,0.9143,368.76556,0.6868,861.13687,0.9143,0.39646071,19.796167,0.23013662,95.325948,0,0,1,,,,4.4206E-5,38.83757,1385.9498,13.22571,0
3888594.44,,5905,38.0072,38.1323,-0.056,9.3E-6,38.234984,0.7666095,512.06526,0.9839,385.97982,0.7257,898.04508,0.9839,0.30094078,20.222707,0.23157255,95.399857,0,0,1,,,,4.5112E-5,39.80074,1461.914,13.392585,0
3889293.44,,5905,39.0072,39.1335,-0.056,9.3E-6,39.242589,0.7870016,532.12237,1.052,403.39111,0.7865,935.51348,1.052,0.23132209,20.713735,0.23742372,95.399778,0,0,1,,,,4.5877E-5,40.75453,1539.9808,13.559818,0
3890000.63,,5905,40.0056,40.137,-0.056,9.3E-6,40.248091,0.80690408,552.56651,1.089,420.93927,0.8688,973.50578,1.089,0.34675736,21.170232,0.24428379,95.373023,0,0,1,,,,4.6712E-5,41.72445,1619.9088,13.729011,0
3891377.39,,5905,5.19069,5.2843,-0.056,9.2E-6,5.2671672,0.10504875,93.549957,0.2619,5.0722693,0.01402,98.622226,0.2619,0.31769615,19.443049,0.020624503,97.786218,0,0,1,,,,5.1758E-6,34.60243,27.74305,17.760962,0
3891952.11,,5905,5.23765,5.3358,-0.056,9.3E-6,5.3180984,0.10806925,94.69335,0.1818,5.2117185,0.01425,99.905068,0.1818,0.20157367,19.219663,0.02048781,97.805473,0,0,1,,,,5.303E-6,37.79289,28.282171,17.805866,0
3892529.95,,5905,5.28214,5.3807,-0.056,9.2E-6,5.3658895,0.11271718,90.63084,0.3928,5.3488513,0.01437,95.979691,0.3928,1.1623368,18.648267,0.023717403,97.535143,0,0,1,,,,5.263E-6,37.64723,28.79277,16.89018,0
3893120.88,,5905,5.32761,5.4297,-0.056,9.3E-6,5.4114671,0.12190207,79.674747,0.7688,5.4837272,0.01441,85.158475,0.7688,8.8274466,17.199651,0.033036131,96.730604,0,0,1,,,,5.098E-6,36.5406,29.283976,14.723317,0
3893676.02,,5905,5.37141,5.4765,-0.056,9.3E-6,5.4568218,0.13137314,65.941592,0.8463,5.6206513,0.0144,71.562243,0.8463,12.081299,14.974968,0.042005863,96.010789,0,0,1,,,,4.9479E-6,33.3777,29.776905,12.084249,0
3894204.34,,5905,5.41414,5.5197,-0.056,9.3E-6,5.501218,0.13215037,55.556721,0.5806,5.7548552,0.01435,61.311576,0.5806,8.6922603,12.414466,0.037632299,96.348333,0,0,1,,,,5.0929E-6,28.57775,30.2634,10.098986,0
3894678.03,,5905,5.45571,5.5597,-0.056,9.4E-6,5.5439443,0.12518958,50.087738,0.3154,5.885855,0.01431,55.973593,0.3154,3.2837492,10.647611,0.026694829,97.290579,0,0,1,,,,5.3744E-6,23.58982,30.735318,9.0346756,0
3895100.95,,5905,5.50078,5.609,-0.056,9.3E-6,5.5859299,0.12136333,46.74894,0.1513,6.0160026,0.01427,52.764943,0.1513,1.1476643,9.8132677,0.026191299,97.315933,0,0,1,,,,5.4936E-6,20.77189,31.202613,8.3690524,0
3895518.52,,5905,5.54344,5.6509,-0.056,9.3E-6,5.6312718,0.11743107,45.894722,0.08629,6.1579981,0.01427,52.05272,0.08629,0.4122151,9.1603652,0.018466506,98.045805,0,0,1,,,,5.7706E-6,19.26148,31.711223,8.1499744,0
3895908.89,,5905,5.58606,5.6935,-0.056,9.3E-6,5.6729328,0.11650586,45.151406,0.08001,6.2913933,0.01431,51.442799,0.08001,0.16663439,9.0311983,0.021499661,97.754429,0,0,1,,,,5.7972E-6,18.33592,32.182166,7.9590941,0
3895983.77,,5905,5.59222,5.702,-0.056,9.3E-6,5.6789949,0.11849437,44.986739,0.09635,6.3110186,0.01432,51.297757,0.09635,0.36655963,8.9630878,0.02159092,97.739273,0,0,1,,,,5.8253E-6,18.0624,32.250983,7.9216023,0